Workbook

Sheet TONG_QUAN
A1: PROJECT_ID | B1: PROJECT_NAME | C1: STATUS | D1: CREATED_AT | E1: LAST_UPDATED_AT | F1: ROOT_FOLDER_ID | G1: ROOT_FOLDER_URL | H1: INDEX_SPREADSHEET_ID | I1: INDEX_SPREADSHEET_URL | J1: CURRENT_BATCH_ID | K1: NOTE
A2: PROJECT_TNTH_001 | B2: NGAN_HANG_DE_TIN_HOC_TOT_NGHIEP | C2: ACTIVE | D2: 2026-07-17T16:00:00+07:00 | E2: 2026-08-09T10:36:00+07:00 | J2: PERIODIC_MATRIX_REVALIDATION_STANDARDIZATION_001 | K2: Đã kiểm định và kích hoạt 24 ma trận kiểm tra định kỳ vận hành cho G10/G11/G12, CS/ICT, GKI/CKI/GKII/CKII. Mỗi blueprint 45 phút, 10 điểm, 20 lệnh; cấu trúc MCQ/TRUE_FALSE_GROUP thay đổi theo tính khả thi của pool. 333 BLUEPRINT_CELLS + 333 BLUEPRINT_SLOTS đều APPROVED, Question_ID slot để trống để bốc động, Family_ID feasibility PASS. Phạm vi nội dung dùng hard gate hoàn thành trước mốc kiểm tra và ALLOWED_FOR_TESTING=TRUE. Pool periodic sau chuẩn hóa: G10=79, G11=57, G12=35; 59 câu được điều chuyển từ graduation do mô hình trạng thái đơn và bổ sung 3 câu G11 từ SGV. Pool graduation còn 529; 10/10 blueprint TN THPT đã kiểm định hồi quy và vẫn khả thi 28/28. Source/provenance matrices không được promote. SGK full-text chưa đăng ký nên chỉ khẳng định đối chiếu cấu trúc bằng tài liệu giới thiệu/tập huấn chính thức và nội dung SGV đã kiểm tra mục tiêu; không khẳng định full-SGK textual review. FILES_CREATED=0; SOURCE_FILES_MODIFIED=0; BACKUP_CREATED=0.

Sheet FILES
A1: FILE_ID | B1: FILE_NAME | C1: MIME_TYPE | D1: PARENT_FOLDER_ID | E1: FOLDER_PATH | F1: DRIVE_URL | G1: SOURCE_GROUP | H1: FILE_STATUS | I1: CHECKSUM | J1: CREATED_AT | K1: MODIFIED_AT | L1: INDEXED_AT | M1: NOTE
A2: 1ydZmskhepIWC-SFHUfCDs-DUXHbadLLY | B2: Slide Giới thiệu SGK Tin học 10.pptx | C2: application/vnd.openxmlformats-officedocument.presentationml.presentation | D2: 16XttQMCyyCdl-LZebMlwyvPGDyDEdbRd | E2: NGAN_HANG_DE_TIN_HOC_TOT_NGHIEP/01_NGUON_CUA_TOI/00_SGK_CHUAN_NXBGDVN/TIN_HOC_10 | F2: https://docs.google.com/presentation/d/1ydZmskhepIWC-SFHUfCDs-DUXHbadLLY/edit?usp=drivesdk | G2: SGK_CHUAN_NXBGDVN|BO=Kết nối tri thức với cuộc sống|LOP=10|SACH=Tin học 10|NXB=Nhà xuất bản Giáo dục Việt Nam|NAM_XUAT_BAN_LAN_DAU=2022|NAM_TAI_BAN_CUA_TEP=NEEDS_REVIEW|LOAI=SLIDE_GIOI_THIEU_CHINH_THUC|NGUON_GOC=taphuan.nxbgd.vn|BATCH_ID=CURR_001 | H2: PARSED | J2: 2026-07-17T10:13:26.542Z | K2: 2026-07-17T10:13:26.542Z
A3: 1EaqbGbTqRalQrImSGw8bfPDI9IMQZhQJ | B3: Slide phục vụ bồi dưỡng GV SGK Tin học 10.pptx | C3: application/vnd.openxmlformats-officedocument.presentationml.presentation | D3: 16XttQMCyyCdl-LZebMlwyvPGDyDEdbRd | E3: NGAN_HANG_DE_TIN_HOC_TOT_NGHIEP/01_NGUON_CUA_TOI/00_SGK_CHUAN_NXBGDVN/TIN_HOC_10 | F3: https://docs.google.com/presentation/d/1EaqbGbTqRalQrImSGw8bfPDI9IMQZhQJ/edit?usp=drivesdk | G3: SGK_CHUAN_NXBGDVN|BO=Kết nối tri thức với cuộc sống|LOP=10|SACH=Tin học 10|NXB=Nhà xuất bản Giáo dục Việt Nam|NAM_XUAT_BAN_LAN_DAU=2022|NAM_TAI_BAN_CUA_TEP=NEEDS_REVIEW|LOAI=SLIDE_BOI_DUONG_GV_CHINH_THUC|NGUON_GOC=taphuan.nxbgd.vn|BATCH_ID=CURR_001 | H3: PARSED | J3: 2026-07-17T10:15:43.710Z | K3: 2026-07-17T10:15:43.710Z | M3: QUESTION_EXTRACTION_BATCH=GUIDANCE_SAMPLE_QUESTION_IMPORT_001; DIRECT_SAMPLE_QUESTIONS_ADDED=1; SOURCE_SLIDE=74; FULL_QUESTION_SCAN=TRUE; SAMPLE_SOURCE_SCAN_DATE=2026-07-28
A4: 1n80cGo7qF3Xjd4rSGFB-ntiwak9ATUX3 | B4: Slide Giới thiệu SGK Tin học 11.pptx | C4: application/vnd.openxmlformats-officedocument.presentationml.presentation | D4: 1SLzzTZI9cif-iZDFzlgV9weaRL5wpDkh | E4: NGAN_HANG_DE_TIN_HOC_TOT_NGHIEP/01_NGUON_CUA_TOI/00_SGK_CHUAN_NXBGDVN/TIN_HOC_11 | F4: https://docs.google.com/presentation/d/1n80cGo7qF3Xjd4rSGFB-ntiwak9ATUX3/edit?usp=drivesdk | G4: SGK_CHUAN_NXBGDVN|BO=Kết nối tri thức với cuộc sống|LOP=11|SACH=Tin học 11 - Định hướng Tin học ứng dụng; Tin học 11 - Định hướng Khoa học máy tính|NXB=Nhà xuất bản Giáo dục Việt Nam|NAM_XUAT_BAN_LAN_DAU=2023|NAM_TAI_BAN_CUA_TEP=NEEDS_REVIEW|LOAI=SLIDE_GIOI_THIEU_CHINH_THUC|NGUON_GOC=taphuan.nxbgd.vn|BATCH_ID=CURR_001 | H4: PARSED | J4: 2026-07-17T10:13:38.373Z | K4: 2026-07-17T10:13:38.373Z
A5: 17OgTqguaSb6BUAi9MEyOXfJkrEX0QNBJ | B5: Slide bồi dưỡng giáo viên Tin học 11.pptx | C5: application/vnd.openxmlformats-officedocument.presentationml.presentation | D5: 1SLzzTZI9cif-iZDFzlgV9weaRL5wpDkh | E5: NGAN_HANG_DE_TIN_HOC_TOT_NGHIEP/01_NGUON_CUA_TOI/00_SGK_CHUAN_NXBGDVN/TIN_HOC_11 | F5: https://docs.google.com/presentation/d/17OgTqguaSb6BUAi9MEyOXfJkrEX0QNBJ/edit?usp=drivesdk | G5: SGK_CHUAN_NXBGDVN|BO=Kết nối tri thức với cuộc sống|LOP=11|SACH=Tin học 11 - Định hướng Tin học ứng dụng; Tin học 11 - Định hướng Khoa học máy tính|NXB=Nhà xuất bản Giáo dục Việt Nam|NAM_XUAT_BAN_LAN_DAU=2023|NAM_TAI_BAN_CUA_TEP=NEEDS_REVIEW|LOAI=SLIDE_BOI_DUONG_GV_CHINH_THUC|NGUON_GOC=taphuan.nxbgd.vn|BATCH_ID=CURR_001 | H5: PARSED | J5: 2026-07-17T10:16:04.392Z | K5: 2026-07-17T10:16:04.392Z | M5: QUESTION_EXTRACTION_BATCH=GUIDANCE_SAMPLE_QUESTION_IMPORT_001; DIRECT_SAMPLE_QUESTIONS_ADDED=1; SOURCE_SLIDE=40_AND_SPEAKER_NOTES; TIME_SENSITIVE_MYSQL_RANKING_ITEMS_EXCLUDED=2; FULL_QUESTION_SCAN=TRUE; SAMPLE_SOURCE_SCAN_DATE=2026-07-28
A6: 1o_x0-CLN_lav2IGnWD7W13mF95Hfzcoi | B6: Slide Giới thiệu SGK Tin học 12.pptx | C6: application/vnd.openxmlformats-officedocument.presentationml.presentation | D6: 1RR3nwmPFeHykktz5BuUHjGYVH8zw4_FI | E6: NGAN_HANG_DE_TIN_HOC_TOT_NGHIEP/01_NGUON_CUA_TOI/00_SGK_CHUAN_NXBGDVN/TIN_HOC_12 | F6: https://docs.google.com/presentation/d/1o_x0-CLN_lav2IGnWD7W13mF95Hfzcoi/edit?usp=drivesdk | G6: SGK_CHUAN_NXBGDVN|BO=Kết nối tri thức với cuộc sống|LOP=12|SACH=Tin học 12 - Định hướng Tin học ứng dụng; Tin học 12 - Định hướng Khoa học máy tính|NXB=Nhà xuất bản Giáo dục Việt Nam|NAM_XUAT_BAN_LAN_DAU=2024|NAM_TAI_BAN_CUA_TEP=NEEDS_REVIEW|LOAI=SLIDE_GIOI_THIEU_CHINH_THUC|NGUON_GOC=taphuan.nxbgd.vn|BATCH_ID=CURR_001 | H6: PARSED | J6: 2026-07-17T10:13:47.468Z | K6: 2026-07-17T10:13:47.468Z
A7: 1dfD3fV2wiMrZMs4HkX409gIgEbwKHwSL | B7: Slide bồi dưỡng giáo viên Tin học 12 - Phần 1.pptx | C7: application/vnd.openxmlformats-officedocument.presentationml.presentation | D7: 1RR3nwmPFeHykktz5BuUHjGYVH8zw4_FI | E7: NGAN_HANG_DE_TIN_HOC_TOT_NGHIEP/01_NGUON_CUA_TOI/00_SGK_CHUAN_NXBGDVN/TIN_HOC_12 | F7: https://docs.google.com/presentation/d/1dfD3fV2wiMrZMs4HkX409gIgEbwKHwSL/edit?usp=drivesdk | G7: SGK_CHUAN_NXBGDVN|BO=Kết nối tri thức với cuộc sống|LOP=12|SACH=Tin học 12 - Định hướng Tin học ứng dụng; Tin học 12 - Định hướng Khoa học máy tính|NXB=Nhà xuất bản Giáo dục Việt Nam|NAM_XUAT_BAN_LAN_DAU=2024|NAM_TAI_BAN_CUA_TEP=NEEDS_REVIEW|LOAI=SLIDE_BOI_DUONG_GV_CHINH_THUC_PHAN_1|NGUON_GOC=taphuan.nxbgd.vn|BATCH_ID=CURR_001 | H7: PARSED | J7: 2026-07-17T10:16:13.963Z | K7: 2026-07-17T10:16:13.963Z
A8: 1nzvZwjRBWqgJ7oTxgo8oLv2uzHrhs4nV | B8: Slide bồi dưỡng giáo viên Tin học 12 - Phần 2.pptx | C8: application/vnd.openxmlformats-officedocument.presentationml.presentation | D8: 1RR3nwmPFeHykktz5BuUHjGYVH8zw4_FI | E8: NGAN_HANG_DE_TIN_HOC_TOT_NGHIEP/01_NGUON_CUA_TOI/00_SGK_CHUAN_NXBGDVN/TIN_HOC_12 | F8: https://docs.google.com/presentation/d/1nzvZwjRBWqgJ7oTxgo8oLv2uzHrhs4nV/edit?usp=drivesdk | G8: SGK_CHUAN_NXBGDVN|BO=Kết nối tri thức với cuộc sống|LOP=12|SACH=Tin học 12 - Định hướng Tin học ứng dụng; Tin học 12 - Định hướng Khoa học máy tính|NXB=Nhà xuất bản Giáo dục Việt Nam|NAM_XUAT_BAN_LAN_DAU=2024|NAM_TAI_BAN_CUA_TEP=NEEDS_REVIEW|LOAI=SLIDE_BOI_DUONG_GV_CHINH_THUC_PHAN_2|NGUON_GOC=taphuan.nxbgd.vn|BATCH_ID=CURR_001 | H8: PARSED | J8: 2026-07-17T10:16:22.775Z | K8: 2026-07-17T10:16:22.775Z | M8: QUESTION_EXTRACTION_BATCH=GUIDANCE_SAMPLE_QUESTION_IMPORT_001; DIRECT_SAMPLE_QUESTIONS_ADDED=1; SOURCE_SLIDES=54-55; FULL_QUESTION_SCAN=TRUE; SAMPLE_SOURCE_SCAN_DATE=2026-07-28
A9: 1ZxSxbytWsNYHcx_ApLiFU6dGG5M3c8Oi | B9: Bo-20-de-thi-thu-TN-THPT-2025-Tin-hay-1_1.pdf | C9: application/pdf | D9: 1bB4kCbUPCSJkLPpihwJzXfw7Rs84Ku2B | E9: NGAN_HANG_DE_TIN_HOC_TOT_NGHIEP/01_NGUON_CUA_TOI/00_INBOX_CHO_KIEM_KE | F9: https://drive.google.com/file/d/1ZxSxbytWsNYHcx_ApLiFU6dGG5M3c8Oi/view?usp=drivesdk | G9: FILE_CODE=TNT_F0001|OWNERSHIP=OWNED_BY_USER|OWNER=trung chien Nguyen <chiennt0109@gmail.com>|CLASS=DE_THI_THU_THAM_KHAO|PROPOSED_FOLDER=NGAN_HANG_DE_TIN_HOC_TOT_NGHIEP/01_NGUON_CUA_TOI/05_DE_THI_THU_THAM_KHAO|MOVE_STATUS=WAITING_FOR_APPROVAL|READ_STATUS=TEXT_EXTRACTED|QUESTION_INVENTORY=594|MCQ=480|TRUE_FALSE_GROUP=114|BATCH_ID=QINV_001 | H9: RAW | J9: 2026-07-17T09:53:19.874Z | K9: 2026-07-17T09:02:58.000Z | M9: BATCH=GRADUATION_PRACTICE_PROMOTION_016; SOURCE_EXAM_D15_FULL_MATRIX_CAPTURED=TRUE; SOURCE_BLUEPRINT_CS=BP_SRC_TNT_F0001_D15_2025_CS_V1; SOURCE_BLUEPRINT_ICT=BP_SRC_TNT_F0001_D15_2025_ICT_V1; SOURCE_MATRIX_STATUS=REVIEW; SOURCE_MATRIX_USE=PROVENANCE_AND_SECONDARY_SELECTION_SIGNAL; SOURCE_FILE_MODIFIED=FALSE; BATCH=GRADUATION_PRACTICE_PROMOTION_017; SOURCE_EXAM_D16_FULL_MATRIX_CAPTURED=TRUE; SOURCE_BLUEPRINT_CS=BP_SRC_TNT_F0001_D16_2025_CS_V1; SOURCE_BLUEPRINT_ICT=BP_SRC_TNT_F0001_D16_2025_ICT_V1; SOURCE_MATRIX_STATUS=REVIEW; SOURCE_MATRIX_USE=PROVENANCE_AND_SECONDARY_SELECTION_SIGNAL; SOURCE_FILE_MODIFIED=FALSE; BATCH=GRADUATION_PRACTICE_PROMOTION_018; SOURCE_EXAM_D17_FULL_MATRIX_CAPTURED=TRUE; SOURCE_BLUEPRINT_CS=BP_SRC_TNT_F0001_D17_2025_CS_V1; SOURCE_BLUEPRINT_ICT=BP_SRC_TNT_F0001_D17_2025_ICT_V1; SOURCE_MATRIX_STATUS=REVIEW; SOURCE_MATRIX_USE=PROVENANCE_AND_SECONDARY_SELECTION_SIGNAL; SOURCE_PRINTED_MATRIX=NOT_PRESENT; SOURCE_FILE_MODIFIED=FALSE; BATCH=GRADUATION_PRACTICE_PROMOTION_019; SOURCE_EXAM_D18_FULL_MATRIX_CAPTURED=TRUE; SOURCE_BLUEPRINT_CS=BP_SRC_TNT_F0001_D18_2025_CS_V1; SOURCE_BLUEPRINT_ICT=BP_SRC_TNT_F0001_D18_2025_ICT_V1; SOURCE_MATRIX_STATUS=REVIEW; SOURCE_MATRIX_USE=PROVENANCE_AND_SECONDARY_SELECTION_SIGNAL; SOURCE_PRINTED_MATRIX=NOT_PRESENT; SOURCE_FILE_MODIFIED=FALSE; BATCH=GRADUATION_PRACTICE_PROMOTION_020; SOURCE_EXAM_D19_FULL_MATRIX_CAPTURED=TRUE; SOURCE_BLUEPRINT_CS=BP_SRC_TNT_F0001_D19_2025_CS_V1; SOURCE_BLUEPRINT_ICT=BP_SRC_TNT_F0001_D19_2025_ICT_V1; SOURCE_MATRIX_STATUS=REVIEW; SOURCE_MATRIX_USE=PROVENANCE_AND_SECONDARY_SELECTION_SIGNAL; SOURCE_PRINTED_MATRIX=NOT_PRESENT; SOURCE_TF_KEYS_MISSING=D19_029|D19_030; SOURCE_FILE_MODIFIED=FALSE; BATCH=GRADUATION_PRACTICE_PROMOTION_021; SOURCE_EXAM_D20_FULL_MATRIX_CAPTURED=TRUE; SOURCE_BLUEPRINT_CS=BP_SRC_TNT_F0001_D20_2025_CS_V1; SOURCE_BLUEPRINT_ICT=BP_SRC_TNT_F0001_D20_2025_ICT_V1; SOURCE_MATRIX_STATUS=REVIEW; SOURCE_MATRIX_USE=PROVENANCE_AND_SECONDARY_SELECTION_SIGNAL; SOURCE_PRINTED_MATRIX=NOT_PRESENT; SOURCE_FILE_MODIFIED=FALSE
A10: 1mrOpGUUroM5RU3Y8lLCsp49qRsofo37q | B10: 09-tinhoc-5889-5120.pdf | C10: application/pdf | D10: 1bB4kCbUPCSJkLPpihwJzXfw7Rs84Ku2B | E10: NGAN_HANG_DE_TIN_HOC_TOT_NGHIEP/01_NGUON_CUA_TOI/00_INBOX_CHO_KIEM_KE | F10: https://drive.google.com/file/d/1mrOpGUUroM5RU3Y8lLCsp49qRsofo37q/view?usp=drivesdk | G10: FILE_CODE=TNT_F0002|OWNERSHIP=OWNED_BY_USER|OWNER=trung chien Nguyen <chiennt0109@gmail.com>|CLASS=DE_MINH_HOA_CHINH_THUC|PROPOSED_FOLDER=NGAN_HANG_DE_TIN_HOC_TOT_NGHIEP/01_NGUON_CUA_TOI/03_DE_MINH_HOA_CHINH_THUC|MOVE_STATUS=WAITING_FOR_APPROVAL|READ_STATUS=READ_BY_RENDER|SOURCE_SUMMARY=Đề tham khảo Bộ GDĐT kỳ thi tốt nghiệp THPT từ năm 2025, môn Tin học|QUESTION_INVENTORY=30|MCQ=24|TRUE_FALSE_GROUP=6|BATCH_ID=QINV_001 | H10: PARSED | J10: 2026-07-17T09:53:16.858Z | K10: 2026-07-17T08:31:14.000Z | L10: 2026-08-06T17:15:00+07:00 | M10: BATCH=GRADUATION_PRACTICE_PROMOTION_023; FULL_VISUAL_REVIEW=TRUE; SOURCE_PAGES=1_TO_5; CANDIDATE_SOURCE_KEYS_VERIFIED=14_OF_14; QUESTION_INVENTORY_ALREADY_REGISTERED=30; CONTENT_EQUIVALENCE_WITH_OFFICIAL_FILE_ID=12wmrtroly93zBrwH33-VMMVDaKW7cbwq; FILE_STATUS_TRANSITION=RAW_TO_PARSED; MOVE_STATUS_UNCHANGED=WAITING_FOR_APPROVAL; SOURCE_FILE_MODIFIED=FALSE; BACKUP_CREATED=0
A11: 1N80P89KS3iY4AS_2oAj2zlt6GFr_MRuChnq1NXMLHMQ | B11: PHAN_PHOI_CHUONG_TRINH_TIN_HOC_10_11_12_TU_SLIDE_TAP_HUAN | C11: application/vnd.google-apps.spreadsheet | D11: 1CchpCp5crg6mWll53RV5X6_JF6cD19qv | E11: NGAN_HANG_DE_TIN_HOC_TOT_NGHIEP/01_NGUON_CUA_TOI/01_KE_HOACH_DAY_HOC | F11: https://docs.google.com/spreadsheets/d/1N80P89KS3iY4AS_2oAj2zlt6GFr_MRuChnq1NXMLHMQ/edit | G11: KE_HOACH_DAY_HOC|LOP=10,11,12|DINH_HUONG=ICT,CS|NGUON=SLIDE_TAP_HUAN_GV|BATCH_ID=YCCD_003 | H11: PARSED | J11: 2026-07-21T17:07:10+07:00 | K11: 2026-07-21T17:07:10+07:00 | L11: 2026-07-21T17:07:10+07:00 | M11: 7 tab: hướng dẫn và 6 phân phối lớp/định hướng. Các ranh giới chưa có kế hoạch trường được đánh dấu WAITING_FOR_APPROVAL/NEEDS_REVIEW; chưa nhập TEACHING_PLANS do thiếu năm học phê duyệt.
A12: 1HPwGbARcvWLH768bfCcm67UHmtAHbPsnoAD7DQHgetQ | B12: MA_TRAN_KIEM_TRA_DINH_KY_TIN_HOC_10_11_12 | C12: application/vnd.google-apps.spreadsheet | D12: 1HML0jHhKw5wLyoUhugzwpq2qa015RgbE | E12: NGAN_HANG_DE_TIN_HOC_TOT_NGHIEP/03_KET_QUA_XU_LY/02_MA_TRAN_VA_DAC_TA | F12: https://docs.google.com/spreadsheets/d/1HPwGbARcvWLH768bfCcm67UHmtAHbPsnoAD7DQHgetQ/edit | G12: MA_TRAN_KIEM_TRA|LOP=10,11,12|DINH_HUONG=ICT,CS|KY=GKI,CKI,GKII,CKII|BATCH_ID=YCCD_003 | H12: PARSED | J12: 2026-07-21T17:07:10+07:00 | K12: 2026-07-21T17:07:10+07:00 | L12: 2026-08-07T17:22:00+07:00 | M12: 2026-08-07T17:22:00+07:00 | N12: 25 tab: tổng quan và 24 ma trận định kỳ G10–G12, CS/ICT, GKI/CKI/GKII/CKII. BATCH=BLUEPRINT_NAMING_G10_G11_INVENTORY_001: đã gán MATRIX_ID và MATRIX_NAME ổn định theo khối–kỳ–năm học–định hướng–phiên bản; giữ WAITING_FOR_APPROVAL. Cột Câu nguồn có là thống kê lịch sử từ 608 câu, không phải READY_FOR_PERIODIC hiện hành.
A13: 13cbU7LC3Wx6vgmTN5wkAXvLzjrnIIJB1 | B13: zssTMTLHoi.pdf | C13: application/pdf | E13: SHARED_WITH_ME/UNFILED | F13: https://drive.google.com/file/d/13cbU7LC3Wx6vgmTN5wkAXvLzjrnIIJB1/view?usp=drivesdk | G13: SGK_CHUAN_NXBGDVN|BO=Kết nối tri thức với cuộc sống|LOP=10|SACH=Tin học 10 - Sách giáo viên|NXB=Nhà xuất bản Giáo dục Việt Nam|LOAI=SACH_GIAO_VIEN|OWNERSHIP=SHARED_SOURCE|SOURCE_VISIBILITY=ACCESS_VERIFIED|BATCH_ID=SOURCE_REGISTER_SGV10_001 | H13: RAW | I13: SHA256:c5cb2f787e365751dfde95ab09a1a2d752c180f2060e7aa2f2541fa3b8a992fc | J13: 2022-07-02T00:13:32.194Z | K13: 2022-07-02T00:13:39.596Z | L13: 2026-07-23T06:22:39+07:00 | M13: DISPLAY_TITLE=Tin học 10 - Sách giáo viên - Kết nối tri thức với cuộc sống; PAGE_COUNT=150; COVER_AND_TITLE_PAGE_VERIFIED=TRUE; CONTENT_EXTRACTION=TARGETED_YCCD_VERIFICATION_ONLY; VERIFIED_PRINTED_PAGES=141,144; VERIFIED_OUTCOME_IDS=TH_10_COMMON_G_B33_YCCD_01,TH_10_COMMON_G_B34_YCCD_01; FULL_PARSE=FALSE; SHORTCUT_STATUS=NOT_CREATED_TOOL_LIMITATION; RECOMMENDED_SHORTCUT_PATH=NGAN_HANG_DE_TIN_HOC_TOT_NGHIEP/02_SHORTCUT_NGUON_CHIA_SE/TIN_HOC_10; ORIGINAL_FILE_NAME=zssTMTLHoi.pdf; BATCH=YCCD_COMPLETE_SGV_001; QUESTION_EXTRACTION_BATCH=SOURCE_BOOK_QUESTION_IMPORT_001; QUESTIONS_ADDED=3; VERIFIED_PRINTED_PAGES_ADDED=17,18,19; QUESTION_IMPORT_SCOPE=TARGETED; FULL_PARSE=FALSE; QUESTION_EXPANSION_BATCH=SOURCE_BOOK_QUESTION_EXPANSION_001; QUESTIONS_ADDED_THIS_BATCH=8; VERIFIED_PRINTED_PAGES_EXPANDED=30,33-36,39-42; TOTAL_EXTRACTED_QUESTIONS=11
A14: 1AWnHQPbdsfoULnvUmWJEp1oTxLbLQM2l | B14: SGV Tin hoc 12-KNTTpdf.pdf | C14: application/pdf | E14: SHARED_WITH_ME/UNFILED | F14: https://drive.google.com/file/d/1AWnHQPbdsfoULnvUmWJEp1oTxLbLQM2l/view?usp=drivesdk | G14: SGK_CHUAN_NXBGDVN|BO=Kết nối tri thức với cuộc sống|LOP=12|SACH=Tin học 12 - Sách giáo viên|NXB=Nhà xuất bản Giáo dục Việt Nam|LOAI=SACH_GIAO_VIEN|OWNERSHIP=SHARED_SOURCE|SOURCE_VISIBILITY=ACCESS_VERIFIED|BATCH_ID=SOURCE_REGISTER_SGV11_SGV12_001 | H14: RAW | I14: SHA256:12a964569011835e232b57f562ae1396fbeac7ddee958efeabe039d1fe421fa9 | J14: 2024-08-17T15:07:06.997Z | K14: 2024-08-17T14:59:07.000Z | L14: 2026-07-23T06:36:26+07:00 | M14: DISPLAY_TITLE=Tin học 12 - Sách giáo viên - Kết nối tri thức với cuộc sống; PAGE_COUNT=226; COVER_AND_TITLE_PAGE_VERIFIED=TRUE; CONTENT_EXTRACTION=TARGETED_YCCD_VERIFICATION_ONLY; VERIFIED_PRINTED_PAGES=128,177,181; VERIFIED_OUTCOME_IDS=TH_12_COMMON_G_B21_YCCD_01,TH_12_CS_F_B29_YCCD_01,TH_12_CS_F_B30_YCCD_01; FULL_PARSE=FALSE; SHORTCUT_STATUS=NOT_CREATED_TOOL_LIMITATION; RECOMMENDED_SHORTCUT_PATH=NGAN_HANG_DE_TIN_HOC_TOT_NGHIEP/02_SHORTCUT_NGUON_CHIA_SE/TIN_HOC_12; ORIGINAL_FILE_NAME=SGV Tin hoc 12-KNTTpdf.pdf; BATCH=YCCD_COMPLETE_SGV_001; QUESTION_EXTRACTION_BATCH=SOURCE_BOOK_QUESTION_IMPORT_001; QUESTIONS_ADDED=3; VERIFIED_PRINTED_PAGES_ADDED=22,23; QUESTION_IMPORT_SCOPE=TARGETED; FULL_PARSE=FALSE; QUESTION_EXPANSION_BATCH=SOURCE_BOOK_QUESTION_EXPANSION_001; QUESTIONS_ADDED_THIS_BATCH=7; VERIFIED_PRINTED_PAGES_EXPANDED=132-133,137-138,155,163,169; TOTAL_EXTRACTED_QUESTIONS=10
A15: 1fJX6oUr8rAVU35bNkIAeLtVpXiaM6LZv | B15: SGV-Tin-hoc-11-KẾT-NỐI-TRI-THỨC.pdf | C15: application/pdf | D15: 1SLzzTZI9cif-iZDFzlgV9weaRL5wpDkh | E15: NGAN_HANG_DE_TIN_HOC_TOT_NGHIEP/01_NGUON_CUA_TOI/00_SGK_CHUAN_NXBGDVN/TIN_HOC_11 | F15: https://drive.google.com/file/d/1fJX6oUr8rAVU35bNkIAeLtVpXiaM6LZv/view?usp=drivesdk | G15: SGK_CHUAN_NXBGDVN|BO=Kết nối tri thức với cuộc sống|LOP=11|SACH=Tin học 11 - Sách giáo viên|NXB=Nhà xuất bản Giáo dục Việt Nam|NAM_XUAT_BAN_LAN_DAU=2023|LOAI=SACH_GIAO_VIEN|OWNERSHIP=OWNED_BY_USER|OWNER=trung chien Nguyen <chiennt0109@gmail.com>|SOURCE_URL=https://thptcphuly.ninhbinh.edu.vn/wp-content/uploads/2026/01/SGV-Tin-hoc-11-K%E1%BA%BET-N%E1%BB%90I-TRI-TH%E1%BB%A8C.pdf|BATCH_ID=SOURCE_REGISTER_SGV11_003 | H15: RAW | I15: SHA256:57767d2698e39f018d1f65ff72094fa1755ada93858febded58e63f5fc6f6020 | J15: 2026-07-22T23:43:52.407Z | K15: 2026-07-22T23:42:34.000Z | L15: 2026-07-23T06:48:49+07:00 | M15: DISPLAY_TITLE=Tin học 11 - Sách giáo viên - Kết nối tri thức với cuộc sống; PAGE_COUNT=218; COVER_VERIFIED=TRUE; PDF_STRUCTURE_VERIFIED=TRUE; CONTENT_EXTRACTION=TARGETED_YCCD_VERIFICATION_ONLY; VERIFIED_PRINTED_PAGES=24,44,48,50,57,85,89,188; VERIFIED_OUTCOME_IDS=TH_11_COMMON_A_B02_YCCD_01,TH_11_COMMON_C_B06_YCCD_01,TH_11_COMMON_C_B07_YCCD_01,TH_11_COMMON_C_B08_YCCD_01,TH_11_COMMON_D_B09_YCCD_01,TH_11_COMMON_F_B15_YCCD_01,TH_11_COMMON_G_B16_YCCD_01,TH_11_ICT_F_B24_YCCD_01; FULL_PARSE=FALSE; SOURCE_LOCATION_VERIFIED=TRUE; PRIOR_ACCESS_LOST_RESOLVED=TRUE; ORIGINAL_EXTERNAL_URL=https://thptcphuly.ninhbinh.edu.vn/wp-content/uploads/2026/01/SGV-Tin-hoc-11-K%E1%BA%BET-N%E1%BB%90I-TRI-TH%E1%BB%A8C.pdf; BATCH=YCCD_COMPLETE_SGV_001; QUESTION_EXTRACTION_BATCH=SOURCE_BOOK_QUESTION_IMPORT_001; QUESTIONS_ADDED=3; VERIFIED_PRINTED_PAGES_ADDED=22,23; QUESTION_IMPORT_SCOPE=TARGETED; FULL_PARSE=FALSE; QUESTION_EXPANSION_BATCH=SOURCE_BOOK_QUESTION_EXPANSION_001; QUESTIONS_ADDED_THIS_BATCH=6; VERIFIED_PRINTED_PAGES_EXPANDED=27,32,39; TOTAL_EXTRACTED_QUESTIONS=9; BATCH=SOURCE_ENRICHMENT_CONSOLIDATION_001; TARGETED_PAGES_ADDED=117,118,119,180,182,191; QUESTIONS_ADDED_THIS_BATCH=7; TOTAL_EXTRACTED_QUESTIONS=16; G11_HKII_CS_QUESTIONS=3; G11_HKII_ICT_QUESTIONS=4; FULL_PARSE=FALSE; BATCH=SOURCE_ENRICHMENT_CONSOLIDATION_002; TARGETED_PAGES_ADDED=127,128,133,134,142,151; QUESTIONS_ADDED_THIS_BATCH=4; TOTAL_EXTRACTED_QUESTIONS=20; G11_CS_NEW_YCCD=B23,B24,B26,B28; FULL_PARSE=FALSE; BATCH=SOURCE_ENRICHMENT_CONSOLIDATION_003; TARGETED_PRINTED_PAGES_ADDED=140,147,155,159,160,161,164; QUESTIONS_ADDED_THIS_BATCH=6; TOTAL_EXTRACTED_QUESTIONS=26; G11_CS_ZERO_COVERAGE_YCCD_FILLED=B25,B27,B29,B30,B31; B30_QUESTIONS=2; FULL_PARSE=FALSE; BATCH=SOURCE_ENRICHMENT_CONSOLIDATION_004; TARGETED_PRINTED_PAGES_ADDED=176,188,189,194,199,203,204,207,210,213; QUESTIONS_ADDED_THIS_BATCH=8; TOTAL_EXTRACTED_QUESTIONS=34; G11_ICT_ZERO_DIRECT_COVERAGE_FILLED=B18,B24,B26,B27,B28,B29,B30,B31; B17_DEFERRED=SOURCE_EXPLICITNESS_GATE; FULL_PARSE=FALSE | O15: DISPLAY_TITLE=Tin học 11 - Sách giáo viên - Kết nối tri thức với cuộc sống; PAGE_COUNT=218; COVER_VERIFIED=TRUE; PDF_STRUCTURE_VERIFIED=TRUE; CONTENT_EXTRACTION=TARGETED_YCCD_VERIFICATION_ONLY; VERIFIED_PRINTED_PAGES=24,44,48,50,57,85,89,188; VERIFIED_OUTCOME_IDS=TH_11_COMMON_A_B02_YCCD_01,TH_11_COMMON_C_B06_YCCD_01,TH_11_COMMON_C_B07_YCCD_01,TH_11_COMMON_C_B08_YCCD_01,TH_11_COMMON_D_B09_YCCD_01,TH_11_COMMON_F_B15_YCCD_01,TH_11_COMMON_G_B16_YCCD_01,TH_11_ICT_F_B24_YCCD_01; FULL_PARSE=FALSE; SOURCE_LOCATION_VERIFIED=TRUE; PRIOR_ACCESS_LOST_RESOLVED=TRUE; ORIGINAL_EXTERNAL_URL=https://thptcphuly.ninhbinh.edu.vn/wp-content/uploads/2026/01/SGV-Tin-hoc-11-K%E1%BA%BET-N%E1%BB%90I-TRI-TH%E1%BB%A8C.pdf; BATCH=YCCD_COMPLETE_SGV_001; QUESTION_EXTRACTION_BATCH=SOURCE_BOOK_QUESTION_IMPORT_001; QUESTIONS_ADDED=3; VERIFIED_PRINTED_PAGES_ADDED=22,23; QUESTION_IMPORT_SCOPE=TARGETED; FULL_PARSE=FALSE; QUESTION_EXPANSION_BATCH=SOURCE_BOOK_QUESTION_EXPANSION_001; QUESTIONS_ADDED_THIS_BATCH=6; VERIFIED_PRINTED_PAGES_EXPANDED=27,32,39; TOTAL_EXTRACTED_QUESTIONS=9; BATCH=SOURCE_ENRICHMENT_CONSOLIDATION_001; TARGETED_PAGES_ADDED=117,118,119,180,182,191; QUESTIONS_ADDED_THIS_BATCH=7; TOTAL_EXTRACTED_QUESTIONS=16; G11_HKII_CS_QUESTIONS=3; G11_HKII_ICT_QUESTIONS=4; FULL_PARSE=FALSE; BATCH=SOURCE_ENRICHMENT_CONSOLIDATION_002; TARGETED_PAGES_ADDED=127,128,133,134,142,151; QUESTIONS_ADDED_THIS_BATCH=4; TOTAL_EXTRACTED_QUESTIONS=20; G11_CS_NEW_YCCD=B23,B24,B26,B28; FULL_PARSE=FALSE; BATCH=SOURCE_ENRICHMENT_CONSOLIDATION_003; TARGETED_PRINTED_PAGES_ADDED=140,147,155,159,160,161,164; QUESTIONS_ADDED_THIS_BATCH=6; TOTAL_EXTRACTED_QUESTIONS=26; G11_CS_ZERO_COVERAGE_YCCD_FILLED=B25,B27,B29,B30,B31; B30_QUESTIONS=2; FULL_PARSE=FALSE; BATCH=SOURCE_ENRICHMENT_CONSOLIDATION_004; TARGETED_PRINTED_PAGES_ADDED=176,188,189,194,199,203,204,207,210,213; QUESTIONS_ADDED_THIS_BATCH=8; TOTAL_EXTRACTED_QUESTIONS=34; G11_ICT_ZERO_DIRECT_COVERAGE_FILLED=B18,B24,B26,B27,B28,B29,B30,B31; B17_DEFERRED=SOURCE_EXPLICITNESS_GATE; FULL_PARSE=FALSE; BATCH=PERIODIC_BLUEPRINT_OPERATIONALIZATION_001; PRIOR_TARGETED_PRINTED_PAGE_INCLUDED=174; REUSED_VERIFIED_PRINTED_PAGES=22,23; TARGETED_PRINTED_PAGE_ADDED=90; QUESTIONS_ADDED_THIS_BATCH=3; TOTAL_EXTRACTED_QUESTIONS=38; G11_B01_OPERATIONAL_TF=1; G11_B16_OPERATIONAL_MCQ=2; FULL_PARSE=FALSE
A16: 10OnzzBPUS8AoypU_PTfaEFbd2uQTj5EpdDaP6s9GKXo | B16: SOURCE_WEB_TECH12H_GKI1_TIN10_KNTT_DE01 | C16: application/vnd.google-apps.document | D16: 1nd_wz75lgvM-527P7sJDtLMy0_KoBd5e | E16: NGAN_HANG_DE_TIN_HOC_TOT_NGHIEP/01_NGUON_CUA_TOI/02_DE_KIEM_TRA_DINH_KY | F16: https://docs.google.com/document/d/10OnzzBPUS8AoypU_PTfaEFbd2uQTj5EpdDaP6s9GKXo/edit?usp=drivesdk | G16: DE_KIEM_TRA_DINH_KY_THAM_KHAO|LOP=10|KY=GKI|BO=Kết nối tri thức|NGUON=tech12h.com|SOURCE_URL=https://tech12h.com/bai-hoc/de-thi-giua-ki-1-tin-hoc-10-kntt-de-tham-khao-so-1|BATCH_ID=TECH12H_GKI10_KNTT_001 | H16: PARSED | J16: 2026-07-31T09:34:59.636Z | K16: 2026-07-31T09:35:18.521Z | L16: 2026-07-31T16:35:42+07:00 | M16: SOURCE_WEB_METADATA_ONLY=TRUE; ORIGINAL_PAGE_NOT_COPIED=TRUE; SOURCE_ITEMS=31; IMPORTED=12; REJECTED=19; COPYRIGHT_PARAPHRASE_ONLY=TRUE; LEGAL_OR_AMBIGUOUS_ITEMS_NOT_IMPORTED=TRUE; BATCH=TECH12H_GKI10_KNTT_001
A17: 12wmrtroly93zBrwH33-VMMVDaKW7cbwq | B17: 09_Tinhoc.pdf | C17: application/pdf | D17: 1sUh3HxfURV9zCsmEHYqeXDZINhV0DizA | E17: DeThamKhao2025 | F17: https://drive.google.com/file/d/12wmrtroly93zBrwH33-VMMVDaKW7cbwq/view?usp=drivesdk | G17: DE_THAM_KHAO_CHINH_THUC|NAM_AP_DUNG=2025|MON=TIN_HOC|CHUONG_TRINH=GDPT_2018|CO_QUAN_CONG_BO=BO_GDDT|BATCH_ID=GRADUATION_POLICY_SETUP_001 | H17: PARSED | J17: 2024-10-19T04:15:28.131Z | K17: 2024-10-19T03:38:06.000Z | L17: 2026-07-26T18:12:09+07:00 | M17: Đăng ký theo Drive ID trước khi dùng làm nguồn hồ sơ chính sách. FILE_SCOPE=OFFICIAL_REFERENCE_EXAM; CONTENT_IMPORT=NOT_PERFORMED; QUESTION_IMPORT=NOT_PERFORMED; STRUCTURE_CROSS_CHECKED_WITH_OFFICIAL_VQA_ANNOUNCEMENT; BATCH=GRADUATION_BLUEPRINT_DRAFT_001; STRUCTURE_PARSED=TRUE; FULL_VISUAL_REVIEW=TRUE; QUESTION_MAPPING_SOURCE=Q_TNT_F0002_001:Q_TNT_F0002_030; CONTENT_EQUIVALENCE_WITH_FILE_ID=1mrOpGUUroM5RU3Y8lLCsp49qRsofo37q; BLUEPRINT_DRAFTS_CREATED=2; STATUS_TRANSITION=RAW_TO_PARSED.
A18: 1nRyadSC8cJoOgFYYhDh11t5PxoVkv0TmODzEyoXuoRo | B18: SOURCE_INDEX_WEB_TECH12H_TIN10_KNTT_EXAMS | C18: application/vnd.google-apps.document | D18: 1nd_wz75lgvM-527P7sJDtLMy0_KoBd5e | E18: NGAN_HANG_DE_TIN_HOC_TOT_NGHIEP/01_NGUON_CUA_TOI/02_DE_KIEM_TRA_DINH_KY | F18: https://docs.google.com/document/d/1nRyadSC8cJoOgFYYhDh11t5PxoVkv0TmODzEyoXuoRo/edit?usp=drivesdk | G18: WEB_SOURCE_INDEX|LOP=10|BO=Kết nối tri thức|NGUON=tech12h.com|DETAIL_URL_COUNT=22|BATCH_ID=TECH12H_INDEX_TIN10_KNTT_001 | H18: PARSED | J18: 2026-07-31T09:57:54.428Z | K18: 2026-07-31T09:58:29.341Z | L18: 2026-07-31T17:02:55+07:00 | M18: SOURCE_INDEX_ONLY=TRUE; ORIGINAL_PAGES_NOT_COPIED=TRUE; DETAIL_URL_COUNT=22; ACCESS_OK=20; ACCESS_LOST=2; ACCESS_LOST_DETAIL=CKII_S8,CKII_S9; PREVIOUS_DETAIL_SOURCE_FILE_ID=10OnzzBPUS8AoypU_PTfaEFbd2uQTj5EpdDaP6s9GKXo; QUESTION_EXTRACTION_MODE=TARGETED_QUALITY_AND_COVERAGE; FULL_PARSE=FALSE; COPYRIGHT_PARAPHRASE_ONLY=TRUE; BATCH=TECH12H_INDEX_TIN10_KNTT_001; BATCH=SOURCE_ENRICHMENT_CONSOLIDATION_001; DETAIL_REVIEWED=GKII_REF02; QUESTIONS_ADDED_THIS_BATCH=7; SOURCE_MATRIX_ADDED=BP_G10_GKII_HK2_SRC_TECH12H_KNTT_02_V1; SOURCE_MATRIX_STATUS=REVIEW_PROVENANCE; PUBLIC_SOURCE_STRUCTURE_COMPLETE=TRUE; REMAINING_ACCESSIBLE_DETAIL_SOURCES_EXIST=TRUE; BATCH=SOURCE_ENRICHMENT_CONSOLIDATION_002; DETAIL_REVIEWED=GKII_REF03,CKII_REF01; GKII_REF03_DECISION=REDUNDANT_WITH_GKII_REF02_NO_IMPORT; CKII_REF01_QUESTIONS_ADDED_THIS_BATCH=1; CKII_REF01_SOURCE_MATRIX=BP_G10_CKII_HK2_SRC_TECH12H_KNTT_01_V1; CKII_REF01_MATRIX_STATUS=REVIEW_PROVENANCE; REMAINING_ACCESSIBLE_DETAIL_SOURCES_EXIST=TRUE; BATCH=SOURCE_ENRICHMENT_CONSOLIDATION_004; DETAIL_REVIEWED=CKII_REF05; CKII_REF05_QUESTIONS_ADDED_THIS_BATCH=0; CKII_REF05_DECISION=NO_HIGH_VALUE_GAP_AFTER_DUPLICATE_COVERAGE_REVIEW; CKII_REF05_SOURCE_MATRIX=BP_G10_CKII_HK2_SRC_TECH12H_KNTT_05_V1; CKII_REF05_MATRIX_STATUS=REVIEW_PROVENANCE; REMAINING_ACCESSIBLE_DETAIL_SOURCES_EXIST=TRUE
A19: 1bP5wDsKSQfk50hY7pVzwQP9g2U1tlX9zVtQZwgrivyQ | B19: SOURCE_INDEX_WEB_KENHGIAOVIEN_TIN10_KNTT_TRUE_FALSE | C19: application/vnd.google-apps.document | D19: 1tFUWFLWPAWqHi0sOgJ6IvJh-3MBU3Czq | E19: NGAN_HANG_DE_TIN_HOC_TOT_NGHIEP/01_NGUON_CUA_TOI/06_TAI_LIEU_HUONG_DAN | F19: https://docs.google.com/document/d/1bP5wDsKSQfk50hY7pVzwQP9g2U1tlX9zVtQZwgrivyQ/edit?usp=drivesdk | G19: WEB_TRUE_FALSE_REFERENCE|LOP=10|BO=Kết nối tri thức|NGUON=kenhgiaovien.com|DETAIL_URL_COUNT=30|BATCH_ID=KENHGIAOVIEN_TF10_KNTT_001 | H19: PARSED | J19: 2026-07-31T10:34:36.478Z | K19: 2026-07-31T10:38:00.044Z | L19: 2026-07-31T17:38:04+07:00 | M19: SOURCE_INDEX_ONLY=TRUE; PUBLIC_SAMPLE_ONLY=TRUE; ORIGINAL_PAGES_NOT_COPIED=TRUE; DETAIL_URL_COUNT=30; IMPORTED_GROUPS=27; IMPORTED_STATEMENTS=108; EXCLUDED_LESSONS=B11,B25,B33; FULL_PARSE=FALSE; COPYRIGHT_PARAPHRASE_ONLY=TRUE; BATCH=KENHGIAOVIEN_TF10_KNTT_001
A20: 1XKLADlKoor4N8E3sjWT_FVHHmeCE85LovLm4XLu57uk | B20: SOURCE_INDEX_WEB_KENHGIAOVIEN_TNTHPT_TINHOC_2025 | C20: application/vnd.google-apps.document | D20: 1iG3bulAYaI_a3cCDB2dvriRNhB1Y-grU | E20: NGAN_HANG_DE_TIN_HOC_TOT_NGHIEP/01_NGUON_CUA_TOI/05_DE_THI_THU_THAM_KHAO | F20: https://docs.google.com/document/d/1XKLADlKoor4N8E3sjWT_FVHHmeCE85LovLm4XLu57uk/edit?usp=drivesdk | G20: WEB_MOCK_GRADUATION_REFERENCE|YEAR=2025|SOURCE=kenhgiaovien.com|DETAIL_URL_COUNT=95|COMPLETED_DETAIL_SOURCES=22|QUESTION_BLUEPRINT_DECOUPLING_V5_REFERENCE_FEASIBILITY=ACTIVE|MATRIX_DUPLICATE_CONTROL=ACTIVE|REFERENCE_CS=BP_TNTHPT_TINHOC_2026_CS_V2|REFERENCE_ICT=BP_TNTHPT_TINHOC_2026_ICT_V2|APPROVED_CALIBRATED_BLUEPRINTS=14|SOURCE_OBSERVED_BLUEPRINTS=22|SOURCE_COLLECTION_EXHAUSTED=FALSE | H20: PARSED | I20: COMPLETED_SOURCE_DETAILS=THANH_HOA,DAK_LAK,HOA_BINH,GIA_LAI,CAN_THO,BAC_NINH,HAU_GIANG,HAI_PHONG,NINH_BINH,HUE,THAI_NGUYEN_2,DONG_THAP,BAC_LIEU,TUYEN_QUANG,DAK_NONG,HOA_BINH_2,NGUYEN_CHI_THANH,THPT_CHUYEN_HUNG_VUONG,THPT_CHUYEN_LE_QUY_DON,THPT_LY_SON,THPT_TAN_SON,THPT_TRAN_VAN_QUAN; LATEST_COMPLETED=THPT_TRAN_VAN_QUAN; TOTAL_QUESTION_ID=764; SOURCE_COLLECTION_EXHAUSTED=FALSE; UNPROCESSED_OR_UNVERIFIED_SOURCES_REMAIN=TRUE; QUESTION_BLUEPRINT_DECOUPLING_V5_REFERENCE_FEASIBILITY=ACTIVE; MATRIX_DUPLICATE_CONTROL=ACTIVE; TVQ_GENERATIVE_BLUEPRINT_REUSE=BP_TNTHPT_TINHOC_2026_CS_V2|BP_TNTHPT_TINHOC_2026_ICT_V2; APPROVED_CALIBRATED_BLUEPRINTS=14 | J20: 2026-07-31T11:26:24.253Z | K20: 2026-07-31T11:28:04.417Z | L20: 2026-08-03T05:58:00+07:00 | M20: SOURCE_INDEX_ONLY=TRUE; PUBLIC_SAMPLE_ONLY=TRUE; ORIGINAL_PAGES_NOT_COPIED=TRUE; DETAIL_URL_COUNT=95; NUMBERED_REFERENCE_EXAMS=52; NAMED_PROVINCIAL_OR_SCHOOL_EXAMS=43; COMPLETED_SOURCES=22; MATRIX_CALIBRATION_RULE=ACTIVE; MATRIX_DUPLICATE_CHECK=REQUIRED; REFERENCE_MATRIX=BP_G12_TNTHPT_TINHOC_2026_CS_V2|BP_G12_TNTHPT_TINHOC_2026_ICT_V2; PAID_OR_HIDDEN_CONTENT_ACCESSED=FALSE; COPYRIGHT_PARAPHRASE_ONLY=TRUE; LATEST_BATCH=KENHGIAOVIEN_TNTHPT_2025_TRANVANQUAN_001; LATEST_SOURCE=THPT_TRAN_VAN_QUAN_BA_RIA_VUNG_TAU; PUBLIC_VISIBLE_PER_ORIENTATION=22_GROUPS_31_COMMANDS; QUESTIONS_ADDED=2; SOURCE_BLUEPRINTS_ADDED=2; SOURCE_MATRIX_EXACT_DUPLICATES=0; CALIBRATED_BLUEPRINTS_ADDED=0; REUSED_REFERENCE_BLUEPRINTS=2; BATCH=SOURCE_ENRICHMENT_CONSOLIDATION_001; DETAIL_REVIEWED=REFERENCE_34; PUBLIC_VISIBLE_SCOPE_COMPLETED=TRUE; QUESTIONS_ADDED_THIS_DETAIL=0; REASON=VISIBLE_SAMPLE_HAS_NO_PUBLISHED_ANSWER_KEY; SOURCE_MATRIX_ADDED=BP_G12_TNTHPT_SRC_KGV_REF34_2025_V1; PARTIAL_SOURCE_MATRIX=TRUE; SOURCE_COLLECTION_EXHAUSTED=FALSE
A21: 1z11SElewCKpGRpwZIkprlBhq009XNjnvU4LdjFsIDCg | B21: SOURCE_WEB_KGV_CKI1_TIN10_KNTT_DE02_MATRIX | C21: application/vnd.google-apps.document | D21: 1nd_wz75lgvM-527P7sJDtLMy0_KoBd5e | E21: NGAN_HANG_DE_TIN_HOC_TOT_NGHIEP/01_NGUON_CUA_TOI/02_DE_KIEM_TRA_DINH_KY | F21: https://docs.google.com/document/d/1z11SElewCKpGRpwZIkprlBhq009XNjnvU4LdjFsIDCg/edit?usp=drivesdk | G21: DE_KIEM_TRA_DINH_KY_THAM_KHAO|LOP=10|KY=CKI|BO=Kết nối tri thức|NGUON=kenhgiaovien.com|SOURCE_URL=https://kenhgiaovien.com/tai-lieu/de-thi-ki-1-tin-hoc-10-ket-noi-tri-thuc-de-so-2|BATCH_ID=PERIODIC_SOURCE_MATRIX_CALIBRATION_002 | H21: PARSED | J21: 2026-08-08T21:29:00+07:00 | K21: 2026-08-08T21:29:00+07:00 | L21: 2026-08-08T21:29:00+07:00 | M21: SOURCE_WEB_METADATA_ONLY=TRUE; PUBLIC_MATRIX_EXTRACTED=TRUE; ORIGINAL_PAGE_NOT_COPIED=TRUE; SOURCE_STRUCTURE=28_MCQ+2_ESSAY; SOURCE_LEVELS_4=NB32.5|TH37.5|VD25|VDC5; THREE_LEVEL_MAPPING=BIET32.5|HIEU37.5|VANDUNG30; COPYRIGHT_PARAPHRASE_ONLY=TRUE; BATCH=PERIODIC_SOURCE_MATRIX_CALIBRATION_002
A22: 1xYUtKt3t0DK3lVsBckRd2dQujwEUMCMkbK8h_Nx2PBA | B22: SOURCE_INDEX_PERIODIC_POOL_BACKFILL_20260810 | C22: application/vnd.google-apps.document | D22: 1nd_wz75lgvM-527P7sJDtLMy0_KoBd5e | E22: NGAN_HANG_DE_TIN_HOC_TOT_NGHIEP/01_NGUON_CUA_TOI/02_DE_KIEM_TRA_DINH_KY | F22: https://docs.google.com/document/d/1xYUtKt3t0DK3lVsBckRd2dQujwEUMCMkbK8h_Nx2PBA/edit | G22: DE_KIEM_TRA_DINH_KY_THAM_KHAO|WEB_SOURCE_INDEX|BATCH_ID=PERIODIC_POOL_FEASIBILITY_AND_BACKFILL_001 | H22: PARSED | J22: 2026-08-10T07:20:00+07:00 | K22: 2026-08-10T07:20:00+07:00 | L22: 2026-08-10T07:20:00+07:00 | M22: SOURCE_INDEX_ONLY=TRUE; SOURCE_TIER=REFERENCE_LOW; URL_LIST_REGISTERED=TRUE; OFFICIAL_SOURCES_REMAIN_PRIORITY=TRUE; COPYRIGHT_PARAPHRASE_ONLY=TRUE; NO_SOURCE_FILE_MODIFIED=TRUE; BATCH=PERIODIC_POOL_FEASIBILITY_AND_BACKFILL_001; BACKUP_CREATED=0

Sheet CURRICULUM
A1: CURRICULUM_ID | B1: GRADE | C1: SUBJECT | D1: PROGRAM_VERSION | E1: TOPIC_CODE | F1: TOPIC_NAME | G1: ORDER_NO | H1: STATUS | I1: NOTE
A2: TH_10_COMMON_A_B01 | B2: 10 | C2: Tin học | D2: GDPT2018_KNTT_COMMON | E2: A | F2: Thông tin và xử lí thông tin | G2: 1 | H2: REVIEW | I2: PHAN=COMMON; CHU_DE=A:Máy tính và xã hội tri thức; NOI_DUNG=Thông tin và xử lí thông tin; BO=Kết nối tri thức với cuộc sống; NXB=NXBGDVN; NAM_XB_LAN_DAU=2022; SOURCE=1EaqbGbTqRalQrImSGw8bfPDI9IMQZhQJ; SLIDE=26; BATCH=CURR_001
A3: TH_10_COMMON_A_B02 | B3: 10 | C3: Tin học | D3: GDPT2018_KNTT_COMMON | E3: A | F3: Vai trò của thiết bị thông minh và tin học đối với xã hội | G3: 2 | H3: REVIEW | I3: PHAN=COMMON; CHU_DE=A:Máy tính và xã hội tri thức; NOI_DUNG=Vai trò của thiết bị thông minh và tin học đối với xã hội; BO=Kết nối tri thức với cuộc sống; NXB=NXBGDVN; NAM_XB_LAN_DAU=2022; SOURCE=1EaqbGbTqRalQrImSGw8bfPDI9IMQZhQJ; SLIDE=26; BATCH=CURR_001
A4: TH_10_CS_A_B03 | B4: 10 | C4: Tin học | D4: GDPT2018_KNTT_CS | E4: A | F4: Một số kiểu dữ liệu và dữ liệu văn bản | G4: 3 | H4: REVIEW | I4: PHAN=CS; CHU_DE=A:Máy tính và xã hội tri thức; NOI_DUNG=Một số kiểu dữ liệu và dữ liệu văn bản; BO=Kết nối tri thức với cuộc sống; NXB=NXBGDVN; NAM_XB_LAN_DAU=2022; SOURCE=1EaqbGbTqRalQrImSGw8bfPDI9IMQZhQJ; SLIDE=26; BATCH=CURR_001
A5: TH_10_CS_A_B04 | B5: 10 | C5: Tin học | D5: GDPT2018_KNTT_CS | E5: A | F5: Hệ nhị phân và dữ liệu số nguyên | G5: 4 | H5: REVIEW | I5: PHAN=CS; CHU_DE=A:Máy tính và xã hội tri thức; NOI_DUNG=Hệ nhị phân và dữ liệu số nguyên; BO=Kết nối tri thức với cuộc sống; NXB=NXBGDVN; NAM_XB_LAN_DAU=2022; SOURCE=1EaqbGbTqRalQrImSGw8bfPDI9IMQZhQJ; SLIDE=26; BATCH=CURR_001
A6: TH_10_CS_A_B05 | B6: 10 | C6: Tin học | D6: GDPT2018_KNTT_CS | E6: A | F6: Dữ liệu lôgic | G6: 5 | H6: REVIEW | I6: PHAN=CS; CHU_DE=A:Máy tính và xã hội tri thức; NOI_DUNG=Dữ liệu lôgic; BO=Kết nối tri thức với cuộc sống; NXB=NXBGDVN; NAM_XB_LAN_DAU=2022; SOURCE=1EaqbGbTqRalQrImSGw8bfPDI9IMQZhQJ; SLIDE=26; BATCH=CURR_001
A7: TH_10_CS_A_B06 | B7: 10 | C7: Tin học | D7: GDPT2018_KNTT_CS | E7: A | F7: Dữ liệu âm thanh và hình ảnh | G7: 6 | H7: REVIEW | I7: PHAN=CS; CHU_DE=A:Máy tính và xã hội tri thức; NOI_DUNG=Dữ liệu âm thanh và hình ảnh; BO=Kết nối tri thức với cuộc sống; NXB=NXBGDVN; NAM_XB_LAN_DAU=2022; SOURCE=1EaqbGbTqRalQrImSGw8bfPDI9IMQZhQJ; SLIDE=26; BATCH=CURR_001
A8: TH_10_COMMON_A_B07 | B8: 10 | C8: Tin học | D8: GDPT2018_KNTT_COMMON | E8: A | F8: Thực hành sử dụng thiết bị số thông dụng | G8: 7 | H8: REVIEW | I8: PHAN=COMMON; CHU_DE=A:Máy tính và xã hội tri thức; NOI_DUNG=Thực hành sử dụng thiết bị số thông dụng; BO=Kết nối tri thức với cuộc sống; NXB=NXBGDVN; NAM_XB_LAN_DAU=2022; SOURCE=1EaqbGbTqRalQrImSGw8bfPDI9IMQZhQJ; SLIDE=26; BATCH=CURR_001
A9: TH_10_COMMON_B_B08 | B9: 10 | C9: Tin học | D9: GDPT2018_KNTT_COMMON | E9: B | F9: Mạng máy tính trong cuộc sống hiện đại | G9: 8 | H9: REVIEW | I9: PHAN=COMMON; CHU_DE=B:Mạng máy tính và Internet; NOI_DUNG=Mạng máy tính trong cuộc sống hiện đại; BO=Kết nối tri thức với cuộc sống; NXB=NXBGDVN; NAM_XB_LAN_DAU=2022; SOURCE=1EaqbGbTqRalQrImSGw8bfPDI9IMQZhQJ; SLIDE=26; BATCH=CURR_001
A10: TH_10_COMMON_B_B09 | B10: 10 | C10: Tin học | D10: GDPT2018_KNTT_COMMON | E10: B | F10: An toàn trên không gian mạng | G10: 9 | H10: REVIEW | I10: PHAN=COMMON; CHU_DE=B:Mạng máy tính và Internet; NOI_DUNG=An toàn trên không gian mạng; BO=Kết nối tri thức với cuộc sống; NXB=NXBGDVN; NAM_XB_LAN_DAU=2022; SOURCE=1EaqbGbTqRalQrImSGw8bfPDI9IMQZhQJ; SLIDE=26; BATCH=CURR_001
A11: TH_10_COMMON_B_B10 | B11: 10 | C11: Tin học | D11: GDPT2018_KNTT_COMMON | E11: B | F11: Thực hành khai thác tài nguyên trên Internet | G11: 10 | H11: REVIEW | I11: PHAN=COMMON; CHU_DE=B:Mạng máy tính và Internet; NOI_DUNG=Thực hành khai thác tài nguyên trên Internet; BO=Kết nối tri thức với cuộc sống; NXB=NXBGDVN; NAM_XB_LAN_DAU=2022; SOURCE=1EaqbGbTqRalQrImSGw8bfPDI9IMQZhQJ; SLIDE=26; BATCH=CURR_001
A12: TH_10_COMMON_D_B11 | B12: 10 | C12: Tin học | D12: GDPT2018_KNTT_COMMON | E12: D | F12: Ứng xử trên môi trường số. Nghĩa vụ tôn trọng bản quyền | G12: 11 | H12: REVIEW | I12: PHAN=COMMON; CHU_DE=D:Đạo đức, pháp luật và văn hoá trong môi trường số; NOI_DUNG=Ứng xử trên môi trường số. Nghĩa vụ tôn trọng bản quyền; BO=Kết nối tri thức với cuộc sống; NXB=NXBGDVN; NAM_XB_LAN_DAU=2022; SOURCE=1EaqbGbTqRalQrImSGw8bfPDI9IMQZhQJ; SLIDE=26; BATCH=CURR_001
A13: TH_10_ICT_E_B12 | B13: 10 | C13: Tin học | D13: GDPT2018_KNTT_ICT | E13: E | F13: Phần mềm thiết kế đồ hoạ | G13: 12 | H13: REVIEW | I13: PHAN=ICT; CHU_DE=E:Ứng dụng tin học; NOI_DUNG=Phần mềm thiết kế đồ hoạ; BO=Kết nối tri thức với cuộc sống; NXB=NXBGDVN; NAM_XB_LAN_DAU=2022; SOURCE=1EaqbGbTqRalQrImSGw8bfPDI9IMQZhQJ; SLIDE=26; BATCH=CURR_001
... A118: TH_12_CS_F_B30 | B118: 12 | C118: Tin học | D118: GDPT2018_KNTT_CS | E118: F | F118: Ứng dụng mô phỏng trong giáo dục | G118: 30 | H118: REVIEW | I118: PHAN=CS; CHU_DE=F:Giải quyết vấn đề với sự trợ giúp của máy tính; NOI_DUNG=Ứng dụng mô phỏng trong giáo dục; BO=Kết nối tri thức với cuộc sống; NXB=NXBGDVN; NAM_XB_LAN_DAU=2024; SOURCE=1dfD3fV2wiMrZMs4HkX409gIgEbwKHwSL;1nzvZwjRBWqgJ7oTxgo8oLv2uzHrhs4nV; SLIDE=11; BATCH=CURR_001

Sheet CURRICULUM_OUTCOMES
A1: OUTCOME_ID | B1: CURRICULUM_ID | C1: OUTCOME_CODE | D1: OUTCOME_TEXT | E1: LEVEL | F1: STATUS | G1: NOTE
A2: TH_10_COMMON_A_B01_YCCD_01 | B2: TH_10_COMMON_A_B01 | C2: YCCD_01 | D2: Phân biệt được thông tin và dữ liệu; giải thích được mối quan hệ giữa thông tin, dữ liệu và quá trình xử lí thông tin. | E2: HIEU | F2: REVIEW | G2: SOURCE_FILE_ID=1EaqbGbTqRalQrImSGw8bfPDI9IMQZhQJ; SOURCE_TITLE=Slide phục vụ bồi dưỡng GV SGK Tin học 10; SOURCE_TYPE=SLIDE_TAP_HUAN_GV; SLIDE=39; NORMALIZED_FROM_SLIDE_CONTENT=TRUE; BATCH=YCCD_007; NLS_FRAME=TT02_2025; NLS_LEVEL=NANG_CAO_1; NLS_MAPPING_STATUS=NOT_APPLICABLE_CONFIRMED; NLS_NOT_APPLICABLE=TRUE; NLS_MAPPING_SOURCE=OUTCOME_TEXT+TT02_2025; NLS_MAPPING_METHOD=PROJECT_CLASSIFICATION; NOT_APPLICABLE_BASIS=FOUNDATIONAL_INFORMATION_DATA_CONCEPT_WITHOUT_DIRECT_1.X_TASK; BATCH=G10_OUTCOME_NLS_MAPPING_001; BACKUP_CREATED=0
A3: TH_10_COMMON_A_B02_YCCD_01 | B3: TH_10_COMMON_A_B02 | C3: YCCD_01 | D3: Nêu được đặc điểm cơ bản của thiết bị thông minh; trình bày được vai trò của thiết bị thông minh, Internet vạn vật và tin học trong xã hội, kinh tế tri thức. | E3: HIEU | F3: REVIEW | G3: SOURCE_FILE_ID=1EaqbGbTqRalQrImSGw8bfPDI9IMQZhQJ; SOURCE_TITLE=Slide phục vụ bồi dưỡng GV SGK Tin học 10; SOURCE_TYPE=SLIDE_TAP_HUAN_GV; SLIDE=40; NORMALIZED_FROM_SLIDE_CONTENT=TRUE; BATCH=YCCD_007; NLS_FRAME=TT02_2025; NLS_LEVEL=NANG_CAO_1; NLS_MAPPING_STATUS=APPROVED; NLS_PRIMARY=5.2; NLS_COMPONENTS=5.2; NLS_MAPPING_SOURCE=OUTCOME_TEXT+TT02_2025; NLS_MAPPING_METHOD=PROJECT_CLASSIFICATION; MAPPING_BASIS=SMART_DEVICE_IOT_AS_TECHNOLOGICAL_RESPONSE; BATCH=G10_OUTCOME_NLS_MAPPING_001; BACKUP_CREATED=0
A4: TH_10_CS_A_B03_YCCD_01 | B4: TH_10_CS_A_B03 | C4: YCCD_01 | D4: Trình bày được cách biểu diễn văn bản bằng Unicode và UTF; nhận biết được một số đặc điểm lưu trữ kí tự tiếng Việt. | E4: HIEU | F4: REVIEW | G4: SOURCE_FILE_ID=1EaqbGbTqRalQrImSGw8bfPDI9IMQZhQJ; SOURCE_TITLE=Slide phục vụ bồi dưỡng GV SGK Tin học 10; SOURCE_TYPE=SLIDE_TAP_HUAN_GV; SLIDE=41; NORMALIZED_FROM_SLIDE_CONTENT=TRUE; BATCH=YCCD_007; NLS_FRAME=TT02_2025; NLS_LEVEL=NANG_CAO_1; NLS_MAPPING_STATUS=NOT_APPLICABLE_CONFIRMED; NLS_NOT_APPLICABLE=TRUE; NLS_MAPPING_SOURCE=OUTCOME_TEXT+TT02_2025; NLS_MAPPING_METHOD=PROJECT_CLASSIFICATION; NOT_APPLICABLE_BASIS=FOUNDATIONAL_ENCODING_KNOWLEDGE_WITHOUT_DIRECT_DIGITAL_COMPETENCY_TASK; BATCH=G10_OUTCOME_NLS_MAPPING_001; BACKUP_CREATED=0
A5: TH_10_CS_A_B04_YCCD_01 | B5: TH_10_CS_A_B04 | C5: YCCD_01 | D5: Biểu diễn và chuyển đổi được số nguyên dương giữa hệ thập phân và hệ nhị phân; thực hiện được một số phép tính nhị phân đơn giản. | E5: VANDUNG | F5: REVIEW | G5: SOURCE_FILE_ID=1EaqbGbTqRalQrImSGw8bfPDI9IMQZhQJ; SOURCE_TITLE=Slide phục vụ bồi dưỡng GV SGK Tin học 10; SOURCE_TYPE=SLIDE_TAP_HUAN_GV; SLIDE=42; NORMALIZED_FROM_SLIDE_CONTENT=TRUE; BATCH=YCCD_007; NLS_FRAME=TT02_2025; NLS_LEVEL=NANG_CAO_1; NLS_MAPPING_STATUS=NOT_APPLICABLE_CONFIRMED; NLS_NOT_APPLICABLE=TRUE; NLS_MAPPING_SOURCE=OUTCOME_TEXT+TT02_2025; NLS_MAPPING_METHOD=PROJECT_CLASSIFICATION; NOT_APPLICABLE_BASIS=BINARY_REPRESENTATION_KNOWLEDGE_NOT_DIRECT_NLS_TASK; BATCH=G10_OUTCOME_NLS_MAPPING_001; BACKUP_CREATED=0
A6: TH_10_CS_A_B05_YCCD_01 | B6: TH_10_CS_A_B05 | C6: YCCD_01 | D6: Nêu được các phép toán lôgic cơ bản và thực hiện được phép toán lôgic trên giá trị đúng, sai hoặc dãy bit. | E6: VANDUNG | F6: REVIEW | G6: SOURCE_FILE_ID=1EaqbGbTqRalQrImSGw8bfPDI9IMQZhQJ; SOURCE_TITLE=Slide phục vụ bồi dưỡng GV SGK Tin học 10; SOURCE_TYPE=SLIDE_TAP_HUAN_GV; SLIDE=43; NORMALIZED_FROM_SLIDE_CONTENT=TRUE; BATCH=YCCD_007; NLS_FRAME=TT02_2025; NLS_LEVEL=NANG_CAO_1; NLS_MAPPING_STATUS=NOT_APPLICABLE_CONFIRMED; NLS_NOT_APPLICABLE=TRUE; NLS_MAPPING_SOURCE=OUTCOME_TEXT+TT02_2025; NLS_MAPPING_METHOD=PROJECT_CLASSIFICATION; NOT_APPLICABLE_BASIS=LOGIC_AND_BIT_OPERATION_KNOWLEDGE_NOT_DIRECT_NLS_TASK; BATCH=G10_OUTCOME_NLS_MAPPING_001; BACKUP_CREATED=0
A7: TH_10_CS_A_B06_YCCD_01 | B7: TH_10_CS_A_B06 | C7: YCCD_01 | D7: Trình bày được nguyên lí số hoá âm thanh và hình ảnh; nhận biết được bitrate, độ sâu màu và một số định dạng tệp thông dụng. | E7: HIEU | F7: REVIEW | G7: SOURCE_FILE_ID=1EaqbGbTqRalQrImSGw8bfPDI9IMQZhQJ; SOURCE_TITLE=Slide phục vụ bồi dưỡng GV SGK Tin học 10; SOURCE_TYPE=SLIDE_TAP_HUAN_GV; SLIDE=44; NORMALIZED_FROM_SLIDE_CONTENT=TRUE; BATCH=YCCD_007; NLS_FRAME=TT02_2025; NLS_LEVEL=NANG_CAO_1; NLS_MAPPING_STATUS=NOT_APPLICABLE_CONFIRMED; NLS_NOT_APPLICABLE=TRUE; NLS_MAPPING_SOURCE=OUTCOME_TEXT+TT02_2025; NLS_MAPPING_METHOD=PROJECT_CLASSIFICATION; NOT_APPLICABLE_BASIS=DIGITIZATION_PRINCIPLE_KNOWLEDGE_WITHOUT_CONTENT_CREATION_TASK; BATCH=G10_OUTCOME_NLS_MAPPING_001; BACKUP_CREATED=0
A8: TH_10_COMMON_A_B07_YCCD_01 | B8: TH_10_COMMON_A_B07 | C8: YCCD_01 | D8: Thực hiện được một số thao tác sử dụng thiết bị số thông dụng, nhất là thiết bị di động, để quản lí và khai thác tệp. | E8: VANDUNG | F8: REVIEW | G8: SOURCE_FILE_ID=1EaqbGbTqRalQrImSGw8bfPDI9IMQZhQJ; SOURCE_TITLE=Slide phục vụ bồi dưỡng GV SGK Tin học 10; SOURCE_TYPE=SLIDE_TAP_HUAN_GV; SLIDE=45; NORMALIZED_FROM_SLIDE_CONTENT=TRUE; BATCH=YCCD_007; NLS_FRAME=TT02_2025; NLS_LEVEL=NANG_CAO_1; NLS_MAPPING_STATUS=APPROVED; NLS_PRIMARY=1.3; NLS_COMPONENTS=1.3; NLS_MAPPING_SOURCE=OUTCOME_TEXT+TT02_2025; NLS_MAPPING_METHOD=PROJECT_CLASSIFICATION; MAPPING_BASIS=MANAGE_AND_USE_FILES_ON_DIGITAL_DEVICES; BATCH=G10_OUTCOME_NLS_MAPPING_001; BACKUP_CREATED=0
A9: TH_10_COMMON_B_B08_YCCD_01 | B9: TH_10_COMMON_B_B08 | C9: YCCD_01 | D9: Trình bày được khái niệm và lợi ích của mạng máy tính; phân biệt được mạng LAN, WAN và Internet; nêu được một số dịch vụ Internet thông dụng. | E9: HIEU | F9: REVIEW | G9: SOURCE_FILE_ID=1EaqbGbTqRalQrImSGw8bfPDI9IMQZhQJ; SOURCE_TITLE=Slide phục vụ bồi dưỡng GV SGK Tin học 10; SOURCE_TYPE=SLIDE_TAP_HUAN_GV; SLIDE=47; BATCH=YCCD_003; NLS_FRAME=TT02_2025; NLS_LEVEL=NANG_CAO_1; NLS_MAPPING_STATUS=NOT_APPLICABLE_CONFIRMED; NLS_NOT_APPLICABLE=TRUE; NLS_MAPPING_SOURCE=OUTCOME_TEXT+TT02_2025; NLS_MAPPING_METHOD=PROJECT_CLASSIFICATION; NOT_APPLICABLE_BASIS=NETWORK_CONCEPT_AND_SERVICE_KNOWLEDGE_WITHOUT_DIRECT_DIGITAL_INTERACTION_TASK; BATCH=G10_OUTCOME_NLS_MAPPING_001; BACKUP_CREATED=0
A10: TH_10_COMMON_B_B09_YCCD_01 | B10: TH_10_COMMON_B_B09 | C10: YCCD_01 | D10: Nhận biết được những nguy cơ và tác hại khi tham gia hoạt động trên Internet; biết cách tự bảo vệ và sử dụng Internet an toàn. | E10: HIEU | F10: REVIEW | G10: SOURCE_FILE_ID=1EaqbGbTqRalQrImSGw8bfPDI9IMQZhQJ; SOURCE_TITLE=Slide phục vụ bồi dưỡng GV SGK Tin học 10; SOURCE_TYPE=SLIDE_TAP_HUAN_GV; SLIDE=48; BATCH=YCCD_003; NLS_FRAME=TT02_2025; NLS_LEVEL=NANG_CAO_1; NLS_MAPPING_STATUS=APPROVED; NLS_PRIMARY=4.2; NLS_COMPONENTS=4.1|4.2; NLS_MAPPING_SOURCE=OUTCOME_TEXT+TT02_2025; NLS_MAPPING_METHOD=PROJECT_CLASSIFICATION; MAPPING_BASIS=INTERNET_RISK_PREVENTION_AND_SELF_PROTECTION; BATCH=G10_OUTCOME_NLS_MAPPING_001; BACKUP_CREATED=0
A11: TH_10_COMMON_B_B10_YCCD_01 | B11: TH_10_COMMON_B_B10 | C11: YCCD_01 | D11: Sử dụng được một số tài nguyên Internet như phần mềm dịch và kho học liệu mở để hỗ trợ học tập. | E11: VANDUNG | F11: REVIEW | G11: SOURCE_FILE_ID=1EaqbGbTqRalQrImSGw8bfPDI9IMQZhQJ; SOURCE_TITLE=Slide phục vụ bồi dưỡng GV SGK Tin học 10; SOURCE_TYPE=SLIDE_TAP_HUAN_GV; SLIDE=49; NORMALIZED_FROM_SLIDE_CONTENT=TRUE; BATCH=YCCD_007; NLS_FRAME=TT02_2025; NLS_LEVEL=NANG_CAO_1; NLS_MAPPING_STATUS=APPROVED; NLS_PRIMARY=5.2; NLS_COMPONENTS=5.2; NLS_MAPPING_SOURCE=OUTCOME_TEXT+TT02_2025; NLS_MAPPING_METHOD=PROJECT_CLASSIFICATION; MAPPING_BASIS=USE_DIGITAL_RESOURCES_TO_MEET_LEARNING_NEEDS; BATCH=G10_OUTCOME_NLS_MAPPING_001; BACKUP_CREATED=0
A12: TH_10_COMMON_D_B11_YCCD_01 | B12: TH_10_COMMON_D_B11 | C12: YCCD_01 | D12: Nhận biết và thực hiện được các quy định pháp luật, đạo đức, văn hoá khi đưa tin trên mạng; có ý thức tôn trọng quyền tác giả và giấy phép sử dụng. | E12: VANDUNG | F12: REVIEW | G12: SOURCE_FILE_ID=1EaqbGbTqRalQrImSGw8bfPDI9IMQZhQJ; SOURCE_TITLE=Slide phục vụ bồi dưỡng GV SGK Tin học 10; SOURCE_TYPE=SLIDE_TAP_HUAN_GV; SLIDE=50-51; NORMALIZED_FROM_SLIDE_CONTENT=TRUE; BATCH=YCCD_007; NLS_FRAME=TT02_2025; NLS_LEVEL=NANG_CAO_1; NLS_MAPPING_STATUS=APPROVED; NLS_PRIMARY=3.3; NLS_COMPONENTS=2.5|3.3; NLS_MAPPING_SOURCE=OUTCOME_TEXT+TT02_2025; NLS_MAPPING_METHOD=PROJECT_CLASSIFICATION; MAPPING_BASIS=COPYRIGHT_LICENSES_AND_CULTURAL_ETHICAL_ONLINE_PUBLISHING; BATCH=G10_OUTCOME_NLS_MAPPING_001; BACKUP_CREATED=0
... A33: TH_10_COMMON_F_B32_YCCD_01 | B33: TH_10_COMMON_F_B32 | C33: YCCD_01 | D33: Vận dụng tổng hợp kiến thức Python về xâu, số, cấu trúc điều khiển và hàm để giải quyết bài toán. | E33: VANDUNG | F33: REVIEW | G33: SOURCE_FILE_ID=1EaqbGbTqRalQrImSGw8bfPDI9IMQZhQJ; SOURCE_TITLE=Slide phục vụ bồi dưỡng GV SGK Tin học 10; SOURCE_TYPE=SLIDE_TAP_HUAN_GV; SLIDE=72; NORMALIZED_FROM_SLIDE_CONTENT=TRUE; BATCH=YCCD_007; NLS_FRAME=TT02_2025; NLS_LEVEL=NANG_CAO_1; NLS_MAPPING_STATUS=APPROVED; NLS_PRIMARY=3.4; NLS_COMPONENTS=3.4|5.3; NLS_MAPPING_SOURCE=OUTCOME_TEXT+TT02_2025; NLS_MAPPING_METHOD=PROJECT_CLASSIFICATION; MAPPING_BASIS=INTEGRATE_PROGRAMMING_KNOWLEDGE_TO_SOLVE_PROBLEM; BATCH=G10_OUTCOME_NLS_MAPPING_001; BACKUP_CREATED=0
A34: =IF(CURRICULUM!A34="","",CURRICULUM!A34&"_YCCD_01") -> TH_10_COMMON_G_B33_YCCD_01 | B34: =CURRICULUM!A34 -> TH_10_COMMON_G_B33 | C34: YCCD_01 | D34: Biết được khái niệm, kiến thức và kĩ năng cần có của nghề thiết kế đồ hoạ; biết các ngành học và nhu cầu nhân lực liên quan; tự tìm kiếm, khai thác và chia sẻ được thông tin hướng nghiệp về lĩnh vực này qua môi trường số; biết được những năng lực của bản thân để định hướng nghề nghiệp trong tương lai. | E34: VANDUNG | F34: REVIEW | G34: SOURCE_FILE_ID=13cbU7LC3Wx6vgmTN5wkAXvLzjrnIIJB1; SOURCE_TITLE=Tin học 10 - Sách giáo viên - Kết nối tri thức với cuộc sống; SOURCE_TYPE=SACH_GIAO_VIEN; LESSON=Bài 33 Nghề thiết kế đồ hoạ máy tính; PRINTED_PAGE=141; PDF_PAGE=142; SOURCE_VERIFICATION=VISUAL_RENDER; OUTCOME_TEXT_VERIFIED=TRUE; LEVEL_CLASSIFIED=VANDUNG; PRIOR_PROVISIONAL_SOURCE_REPLACED=TRUE; PRIOR_BATCH=OUTCOME_NEEDS_REVIEW_TRIAGE_001; BATCH=YCCD_COMPLETE_SGV_001; NLS_FRAME=TT02_2025; NLS_LEVEL=NANG_CAO_1; NLS_MAPPING_STATUS=APPROVED; NLS_PRIMARY=1.1; NLS_COMPONENTS=1.1|2.2|5.4; NLS_MAPPING_SOURCE=OUTCOME_TEXT+TT02_2025; NLS_MAPPING_METHOD=PROJECT_CLASSIFICATION; MAPPING_BASIS=DIGITAL_SEARCH_EXPLOIT_SHARE_CAREER_INFORMATION_AND_SELF_COMPETENCY_AWARENESS; BATCH=G10_OUTCOME_NLS_MAPPING_001; BACKUP_CREATED=0
A35: =IF(CURRICULUM!A35="","",CURRICULUM!A35&"_YCCD_01") -> TH_10_COMMON_G_B34_YCCD_01 | B35: =CURRICULUM!A35 -> TH_10_COMMON_G_B34 | C35: YCCD_01 | D35: Hiểu được khái niệm nghề phát triển phần mềm và một số kiến thức, kĩ năng cần có của người làm nghề; biết các ngành học ở bậc đại học, cao đẳng và cơ hội nghề nghiệp liên quan đến phát triển phần mềm; biết được khả năng của bản thân để định hướng nghề nghiệp trong tương lai. | E35: HIEU | F35: REVIEW | G35: SOURCE_FILE_ID=13cbU7LC3Wx6vgmTN5wkAXvLzjrnIIJB1; SOURCE_TITLE=Tin học 10 - Sách giáo viên - Kết nối tri thức với cuộc sống; SOURCE_TYPE=SACH_GIAO_VIEN; LESSON=Bài 34 Nghề phát triển phần mềm; PRINTED_PAGE=144; PDF_PAGE=145; SOURCE_VERIFICATION=VISUAL_RENDER; OUTCOME_TEXT_VERIFIED=TRUE; LEVEL_CLASSIFIED=HIEU; PRIOR_PROVISIONAL_SOURCE_REPLACED=TRUE; PRIOR_BATCH=OUTCOME_NEEDS_REVIEW_TRIAGE_001; BATCH=YCCD_COMPLETE_SGV_001; NLS_FRAME=TT02_2025; NLS_LEVEL=NANG_CAO_1; NLS_MAPPING_STATUS=NOT_APPLICABLE_CONFIRMED; NLS_NOT_APPLICABLE=TRUE; NLS_MAPPING_SOURCE=OUTCOME_TEXT+TT02_2025; NLS_MAPPING_METHOD=PROJECT_CLASSIFICATION; NOT_APPLICABLE_BASIS=CAREER_KNOWLEDGE_AND_SELF_ORIENTATION_WITHOUT_EXPLICIT_DIGITAL_SEARCH_SHARE_OR_DIGITAL_COMPETENCE_TASK; BATCH=G10_OUTCOME_NLS_MAPPING_001; BACKUP_CREATED=0
A36: =IF(CURRICULUM!A36="","",CURRICULUM!A36&"_YCCD_01") -> TH_11_COMMON_A_B01_YCCD_01 | B36: =CURRICULUM!A36 -> TH_11_COMMON_A_B01 | C36: YCCD_01 | D36: Trình bày được một số chức năng cơ bản của hệ điều hành và mối quan hệ giữa hệ điều hành, phần cứng và phần mềm ứng dụng. | E36: HIEU | F36: REVIEW | G36: SOURCE_FILE_ID=17OgTqguaSb6BUAi9MEyOXfJkrEX0QNBJ; SOURCE_TITLE=Slide bồi dưỡng giáo viên Tin học 11; SOURCE_TYPE=SLIDE_TAP_HUAN_GV; SECTION=Bài 1 Hệ điều hành; BATCH=YCCD_003; NLS_FRAME=TT02_2025; NLS_LEVEL=NANG_CAO_1; NLS_MAPPING_STATUS=NOT_APPLICABLE_CONFIRMED; NLS_NOT_APPLICABLE=TRUE; NLS_MAPPING_REASON=YCCD_CHU_YEU_DANH_GIA_KIEN_THUC_KHAI_NIEM_HE_DIEU_HANH; NLS_MAPPING_METHOD=PROJECT_CLASSIFICATION; BATCH=PERIODIC_NLS_AI_G11_G12_MATRIX_001
A37: =IF(CURRICULUM!A37="","",CURRICULUM!A37&"_YCCD_01") -> TH_11_COMMON_A_B02_YCCD_01 | B37: =CURRICULUM!A37 -> TH_11_COMMON_A_B02 | C37: YCCD_01 | D37: Sử dụng được một số chức năng cơ bản của hệ điều hành cho máy tính cá nhân; sử dụng được một số tiện ích của hệ điều hành để nâng cao hiệu quả sử dụng máy tính và thiết bị di động. | E37: VANDUNG | F37: REVIEW | G37: SOURCE_FILE_ID=1fJX6oUr8rAVU35bNkIAeLtVpXiaM6LZv; SOURCE_TITLE=Tin học 11 - Sách giáo viên - Kết nối tri thức với cuộc sống; SOURCE_TYPE=SACH_GIAO_VIEN; LESSON=Bài 2 Thực hành sử dụng hệ điều hành; PRINTED_PAGE=24; PDF_PAGE=25; SOURCE_VERIFICATION=VISUAL_RENDER; OUTCOME_TEXT_VERIFIED=TRUE; LEVEL_CLASSIFIED=VANDUNG; PRIOR_PROVISIONAL_SOURCE_REPLACED=TRUE; PRIOR_BATCH=OUTCOME_NEEDS_REVIEW_TRIAGE_001; BATCH=YCCD_COMPLETE_SGV_001; NLS_FRAME=TT02_2025; NLS_LEVEL=NANG_CAO_1; NLS_MAPPING_STATUS=APPROVED; NLS_PRIMARY=5.2; NLS_COMPONENTS=5.2; NLS_MAPPING_SOURCE=OUTCOME_TEXT+TT02_2025; NLS_MAPPING_METHOD=PROJECT_CLASSIFICATION; BATCH=PERIODIC_NLS_AI_G11_G12_MATRIX_001
A38: =IF(CURRICULUM!A38="","",CURRICULUM!A38&"_YCCD_01") -> TH_11_COMMON_A_B03_YCCD_01 | B38: =CURRICULUM!A38 -> TH_11_COMMON_A_B03 | C38: YCCD_01 | D38: Phân biệt được ba loại phần mềm: phần mềm thương mại, phần mềm tự do và phần mềm nguồn mở. | E38: HIEU | F38: REVIEW | G38: SOURCE_FILE_ID=17OgTqguaSb6BUAi9MEyOXfJkrEX0QNBJ; SOURCE_TITLE=Slide bồi dưỡng giáo viên Tin học 11; SOURCE_TYPE=SLIDE_TAP_HUAN_GV; SLIDE=44; BATCH=YCCD_004; NLS_FRAME=TT02_2025; NLS_LEVEL=NANG_CAO_1; NLS_MAPPING_STATUS=APPROVED; NLS_PRIMARY=3.3; NLS_COMPONENTS=3.3; NLS_MAPPING_SOURCE=OUTCOME_TEXT+TT02_2025; NLS_MAPPING_METHOD=PROJECT_CLASSIFICATION; MAPPING_NOTE=PHAN_LOAI_PHAN_MEM_GAN_VOI_BAN_QUYEN_GIAY_PHEP; BATCH=PERIODIC_NLS_AI_G11_G12_MATRIX_001
A39: =IF(CURRICULUM!A39="","",CURRICULUM!A39&"_YCCD_01") -> TH_11_COMMON_A_B04_YCCD_01 | B39: =CURRICULUM!A39 -> TH_11_COMMON_A_B04 | C39: YCCD_01 | D39: Nhận biết được sơ đồ các mạch lôgic AND, OR, NOT và giải thích được vai trò của chúng trong thực hiện các tính toán nhị phân qua ví dụ cụ thể. | E39: HIEU | F39: REVIEW | G39: SOURCE_FILE_ID=17OgTqguaSb6BUAi9MEyOXfJkrEX0QNBJ; SOURCE_TITLE=Slide bồi dưỡng giáo viên Tin học 11; SOURCE_TYPE=SLIDE_TAP_HUAN_GV; SLIDE=45; BATCH=YCCD_004; NLS_FRAME=TT02_2025; NLS_LEVEL=NANG_CAO_1; NLS_MAPPING_STATUS=NOT_APPLICABLE_CONFIRMED; NLS_NOT_APPLICABLE=TRUE; NLS_MAPPING_REASON=YCCD_CHU_YEU_DANH_GIA_KIEN_THUC_LOGIC_MAY_TINH; NLS_MAPPING_METHOD=PROJECT_CLASSIFICATION; BATCH=PERIODIC_NLS_AI_G11_G12_MATRIX_001
A40: =IF(CURRICULUM!A40="","",CURRICULUM!A40&"_YCCD_01") -> TH_11_COMMON_A_B05_YCCD_01 | B40: =CURRICULUM!A40 -> TH_11_COMMON_A_B05 | C40: YCCD_01 | D40: Nhận biết được một số cổng và công nghệ kết nối thông dụng trên máy tính và thiết bị số. | E40: HIEU | F40: REVIEW | G40: SOURCE_FILE_ID=17OgTqguaSb6BUAi9MEyOXfJkrEX0QNBJ; SOURCE_TITLE=Slide bồi dưỡng giáo viên Tin học 11; SOURCE_TYPE=SLIDE_TAP_HUAN_GV; SECTION=Bài 5 Kết nối máy tính với thiết bị số; BATCH=YCCD_003; NLS_FRAME=TT02_2025; NLS_LEVEL=NANG_CAO_1; NLS_MAPPING_STATUS=APPROVED; NLS_PRIMARY=5.2; NLS_COMPONENTS=5.2; NLS_MAPPING_SOURCE=OUTCOME_TEXT+TT02_2025; NLS_MAPPING_METHOD=PROJECT_CLASSIFICATION; BATCH=PERIODIC_NLS_AI_G11_G12_MATRIX_001
A41: =IF(CURRICULUM!A41="","",CURRICULUM!A41&"_YCCD_01") -> TH_11_COMMON_C_B06_YCCD_01 | B41: =CURRICULUM!A41 -> TH_11_COMMON_C_B06 | C41: YCCD_01 | D41: Sử dụng được một số công cụ trực tuyến để lưu trữ và chia sẻ tệp tin. | E41: VANDUNG | F41: REVIEW | G41: SOURCE_FILE_ID=1fJX6oUr8rAVU35bNkIAeLtVpXiaM6LZv; SOURCE_TITLE=Tin học 11 - Sách giáo viên - Kết nối tri thức với cuộc sống; SOURCE_TYPE=SACH_GIAO_VIEN; LESSON=Bài 6 Lưu trữ và chia sẻ tệp tin trên Internet; PRINTED_PAGE=44; PDF_PAGE=45; SOURCE_VERIFICATION=VISUAL_RENDER; OUTCOME_TEXT_VERIFIED=TRUE; LEVEL_CLASSIFIED=VANDUNG; PRIOR_PROVISIONAL_SOURCE_REPLACED=TRUE; PRIOR_BATCH=OUTCOME_NEEDS_REVIEW_TRIAGE_001; BATCH=YCCD_COMPLETE_SGV_001; NLS_FRAME=TT02_2025; NLS_LEVEL=NANG_CAO_1; NLS_MAPPING_STATUS=APPROVED; NLS_PRIMARY=1.3; NLS_COMPONENTS=1.3|2.2; NLS_MAPPING_SOURCE=OUTCOME_TEXT+TT02_2025; NLS_MAPPING_METHOD=PROJECT_CLASSIFICATION; BATCH=PERIODIC_NLS_AI_G11_G12_MATRIX_001
A42: =IF(CURRICULUM!A42="","",CURRICULUM!A42&"_YCCD_01") -> TH_11_COMMON_C_B07_YCCD_01 | B42: =CURRICULUM!A42 -> TH_11_COMMON_C_B07 | C42: YCCD_01 | D42: Sử dụng được máy tìm kiếm trên máy tính và thiết bị số thông minh bằng từ khoá hoặc tiếng nói; xác lập được các lựa chọn, tiêu chí tìm kiếm để nâng cao hiệu quả. | E42: VANDUNG | F42: REVIEW | G42: SOURCE_FILE_ID=1fJX6oUr8rAVU35bNkIAeLtVpXiaM6LZv; SOURCE_TITLE=Tin học 11 - Sách giáo viên - Kết nối tri thức với cuộc sống; SOURCE_TYPE=SACH_GIAO_VIEN; LESSON=Bài 7 Thực hành tìm kiếm thông tin trên Internet; PRINTED_PAGE=48; PDF_PAGE=49; SOURCE_VERIFICATION=VISUAL_RENDER; OUTCOME_TEXT_VERIFIED=TRUE; LEVEL_CLASSIFIED=VANDUNG; PRIOR_PROVISIONAL_SOURCE_REPLACED=TRUE; PRIOR_BATCH=OUTCOME_NEEDS_REVIEW_TRIAGE_001; BATCH=YCCD_COMPLETE_SGV_001; NLS_FRAME=TT02_2025; NLS_LEVEL=NANG_CAO_1; NLS_MAPPING_STATUS=APPROVED; NLS_PRIMARY=1.1; NLS_COMPONENTS=1.1|1.2; NLS_MAPPING_SOURCE=OUTCOME_TEXT+TT02_2025; NLS_MAPPING_METHOD=PROJECT_CLASSIFICATION; MAPPING_BASIS=SEARCH_INFORMATION_WITH_CRITERIA; BATCH=PERIODIC_BLUEPRINT_PORTFOLIO_COVERAGE_001; BACKUP_CREATED=0
A43: =IF(CURRICULUM!A43="","",CURRICULUM!A43&"_YCCD_01") -> TH_11_COMMON_C_B08_YCCD_01 | B43: =CURRICULUM!A43 -> TH_11_COMMON_C_B08 | C43: YCCD_01 | D43: Biết đánh dấu, phân loại thư điện tử và khai thác được một số chức năng nâng cao của mạng xã hội. | E43: VANDUNG | F43: REVIEW | G43: SOURCE_FILE_ID=1fJX6oUr8rAVU35bNkIAeLtVpXiaM6LZv; SOURCE_TITLE=Tin học 11 - Sách giáo viên - Kết nối tri thức với cuộc sống; SOURCE_TYPE=SACH_GIAO_VIEN; LESSON=Bài 8 Thực hành nâng cao sử dụng thư điện tử và mạng xã hội; PRINTED_PAGE=50; PDF_PAGE=51; SOURCE_VERIFICATION=VISUAL_RENDER; OUTCOME_TEXT_VERIFIED=TRUE; LEVEL_CLASSIFIED=VANDUNG; PRIOR_PROVISIONAL_SOURCE_REPLACED=TRUE; PRIOR_BATCH=OUTCOME_NEEDS_REVIEW_TRIAGE_001; BATCH=YCCD_COMPLETE_SGV_001; NLS_FRAME=TT02_2025; NLS_LEVEL=NANG_CAO_1; NLS_MAPPING_STATUS=APPROVED; NLS_PRIMARY=2.1; NLS_COMPONENTS=2.1|2.2; NLS_MAPPING_SOURCE=OUTCOME_TEXT+TT02_2025; NLS_MAPPING_METHOD=PROJECT_CLASSIFICATION; MAPPING_BASIS=EMAIL_SOCIAL_ADVANCED_COMMUNICATION; BATCH=PERIODIC_BLUEPRINT_PORTFOLIO_COVERAGE_001; BACKUP_CREATED=0
A44: =IF(CURRICULUM!A44="","",CURRICULUM!A44&"_YCCD_01") -> TH_11_COMMON_D_B09_YCCD_01 | B44: =CURRICULUM!A44 -> TH_11_COMMON_D_B09 | C44: YCCD_01 | D44: Nêu được một số dạng lừa đảo phổ biến trên không gian mạng và biện pháp phòng tránh; giao tiếp được trong môi trường số một cách văn minh, phù hợp với quy tắc và văn hoá ứng xử. | E44: VANDUNG | F44: REVIEW | G44: SOURCE_FILE_ID=1fJX6oUr8rAVU35bNkIAeLtVpXiaM6LZv; SOURCE_TITLE=Tin học 11 - Sách giáo viên - Kết nối tri thức với cuộc sống; SOURCE_TYPE=SACH_GIAO_VIEN; LESSON=Bài 9 Giao tiếp an toàn trên Internet; PRINTED_PAGE=57; PDF_PAGE=58; SOURCE_VERIFICATION=VISUAL_RENDER; OUTCOME_TEXT_VERIFIED=TRUE; LEVEL_CLASSIFIED=VANDUNG; PRIOR_PROVISIONAL_SOURCE_REPLACED=TRUE; PRIOR_BATCH=OUTCOME_NEEDS_REVIEW_TRIAGE_001; BATCH=YCCD_COMPLETE_SGV_001; NLS_FRAME=TT02_2025; NLS_LEVEL=NANG_CAO_1; NLS_MAPPING_STATUS=APPROVED; NLS_PRIMARY=4.2; NLS_COMPONENTS=4.2|2.5; NLS_MAPPING_SOURCE=OUTCOME_TEXT+TT02_2025; NLS_MAPPING_METHOD=PROJECT_CLASSIFICATION; MAPPING_BASIS=ONLINE_SCAM_PREVENTION+NETIQUETTE; BATCH=QUESTION_NLS_TASK_MISMATCH_RESOLUTION_001; BACKUP_CREATED=0
A45: =IF(CURRICULUM!A45="","",CURRICULUM!A45&"_YCCD_01") -> TH_11_COMMON_F_B10_YCCD_01 | B45: =CURRICULUM!A45 -> TH_11_COMMON_F_B10 | C45: YCCD_01 | D45: Nêu được nhu cầu lưu trữ và tổ chức dữ liệu một cách khoa học để tạo điều kiện cho việc cập nhật và khai thác dữ liệu. | E45: HIEU | F45: REVIEW | G45: SOURCE_FILE_ID=17OgTqguaSb6BUAi9MEyOXfJkrEX0QNBJ; SOURCE_TITLE=Slide bồi dưỡng giáo viên Tin học 11; SOURCE_TYPE=SLIDE_TAP_HUAN_GV; SLIDE=47; BATCH=YCCD_004; NLS_FRAME=TT02_2025; NLS_LEVEL=NANG_CAO_1; NLS_MAPPING_STATUS=APPROVED; NLS_PRIMARY=1.3; NLS_COMPONENTS=1.3; NLS_MAPPING_SOURCE=OUTCOME_TEXT+TT02_2025; NLS_MAPPING_METHOD=PROJECT_CLASSIFICATION; MAPPING_BASIS=ORGANIZE_DATA_FOR_MANAGEMENT; BATCH=PERIODIC_BLUEPRINT_PORTFOLIO_COVERAGE_001; BACKUP_CREATED=0
... A81: =IF(CURRICULUM!A81="","",CURRICULUM!A81&"_YCCD_01") -> TH_11_CS_F_B31_YCCD_01 | B81: =CURRICULUM!A81 -> TH_11_CS_F_B31 | C81: YCCD_01 | D81: Thực hành thiết lập và sử dụng thư viện chương trình, làm việc với danh sách liên kết. | E81: VANDUNG | F81: REVIEW | G81: SOURCE_FILE_ID=17OgTqguaSb6BUAi9MEyOXfJkrEX0QNBJ; SOURCE_TITLE=Slide bồi dưỡng giáo viên Tin học 11; SOURCE_TYPE=SLIDE_TAP_HUAN_GV; SLIDE=63; NORMALIZED_FROM_SLIDE_CONTENT=TRUE; BATCH=YCCD_006; NLS_FRAME=TT02_2025; NLS_LEVEL=NANG_CAO_1; NLS_MAPPING_STATUS=APPROVED; NLS_PRIMARY=3.4; NLS_COMPONENTS=3.4; NLS_MAPPING_SOURCE=OUTCOME_TEXT+TT02_2025; NLS_MAPPING_METHOD=PROJECT_CLASSIFICATION; BATCH=PERIODIC_NLS_AI_G11_G12_MATRIX_001
A82: TH_12_COMMON_A_B01_YCCD_01 | B82: TH_12_COMMON_A_B01 | C82: YCCD_01 | D82: Giải thích được sơ lược về khái niệm AI. | E82: HIEU | F82: REVIEW | G82: TRÍCH TỪ SLIDE BỒI DƯỠNG GV TIN HỌC 12 - PHẦN 2; NGUON_FILE_ID=1nzvZwjRBWqgJ7oTxgo8oLv2uzHrhs4nV; BATCH_ID=CURR_001; NLS_FRAME=TT02_2025; NLS_LEVEL=NANG_CAO_1; NLS_MAPPING_STATUS=APPROVED; NLS_PRIMARY=6.1; NLS_COMPONENTS=6.1; NLS_MAPPING_SOURCE=OUTCOME_TEXT+TT02_2025; NLS_MAPPING_METHOD=PROJECT_CLASSIFICATION; AI_INTEGRATION=DIRECT; AI_COMPONENT=6.1; AI_FRAME=QD3439_2025; AI_FRAME_SCOPE=PILOT; AI_FRAME_MAPPING_STATUS=PARTIAL_FOUNDATION; AI_FRAME_COMPONENTS=AI_NLc; AI_PILOT_GATE=TEACHING_PLAN_REQUIRED; BATCH=PERIODIC_NLS_AI_G11_G12_MATRIX_001
A83: TH_12_COMMON_A_B02_YCCD_01 | B83: TH_12_COMMON_A_B02 | C83: YCCD_01 | D83: Nhận biết được vai trò và một số ứng dụng của trí tuệ nhân tạo trong khoa học và đời sống. | E83: HIEU | F83: REVIEW | G83: SOURCE_FILE_ID=1o_x0-CLN_lav2IGnWD7W13mF95Hfzcoi; SOURCE_TITLE=Slide Giới thiệu SGK Tin học 12; SOURCE_TYPE=SLIDE_GIOI_THIEU_SGK; SLIDE=9; SOURCE_LOCATION=PRESENTER_NOTES; NORMALIZED_FROM_PRESENTER_NOTES=TRUE; LESSON_SCOPE_INFERRED_FROM_CURRICULUM_TITLE=TRUE; SCOPE_REVIEW_REQUIRED=TRUE; BATCH=YCCD_012; NLS_FRAME=TT02_2025; NLS_LEVEL=NANG_CAO_1; NLS_MAPPING_STATUS=APPROVED; NLS_PRIMARY=6.1; NLS_COMPONENTS=6.1; NLS_MAPPING_SOURCE=OUTCOME_TEXT+TT02_2025; NLS_MAPPING_METHOD=PROJECT_CLASSIFICATION; AI_INTEGRATION=DIRECT; AI_COMPONENT=6.1; AI_FRAME=QD3439_2025; AI_FRAME_SCOPE=PILOT; AI_FRAME_MAPPING_STATUS=PARTIAL_FOUNDATION; AI_FRAME_COMPONENTS=AI_NLa|AI_NLc; AI_PILOT_GATE=TEACHING_PLAN_REQUIRED; BATCH=PERIODIC_NLS_AI_G11_G12_MATRIX_001
A84: =IF(CURRICULUM!A84="","",CURRICULUM!A84&"_YCCD_01") -> TH_12_COMMON_B_B03_YCCD_01 | B84: =CURRICULUM!A84 -> TH_12_COMMON_B_B03 | C84: YCCD_01 | D84: Biết được một số thiết bị mạng thông dụng và chức năng của chúng. | E84: BIET | F84: REVIEW | G84: SOURCE_FILE_ID=1nzvZwjRBWqgJ7oTxgo8oLv2uzHrhs4nV; SOURCE_TITLE=Slide bồi dưỡng giáo viên Tin học 12 - Phần 2; SOURCE_TYPE=TAI_LIEU_BOI_DUONG_GIAO_VIEN; SLIDE=22; DIRECT_REQUIREMENT=TRUE; BATCH=YCCD_002; NLS_FRAME=TT02_2025; NLS_LEVEL=NANG_CAO_1; NLS_MAPPING_STATUS=NOT_APPLICABLE_CONFIRMED; NLS_NOT_APPLICABLE=TRUE; NLS_MAPPING_REASON=YCCD_CHU_YEU_NHAN_BIET_THIET_BI_VA_CHUC_NANG_CHUA_CO_NHIEM_VU_LUA_CHON_SU_DUNG; NLS_MAPPING_METHOD=PROJECT_CLASSIFICATION; BATCH=PERIODIC_NLS_AI_G11_G12_MATRIX_001
